Workbook

Sheet Profit
A1: Month | B1: Year | C1: Lessons Sales | D1: Books | E1: Instructor Payment | F1: Expenses | G1: Staff Salaries | H1: Expired Hours (Legacy) | I1: Distributed Profit | J1: Transfered to Savings | K1: Gross Profit | L1: Net Profit | M1: Cumulative | O1: Cash Available
A2: 7 | B2: 2022 | C2: =Sumproduct(Sales!$F$2:$F999,month(Sales!$A$2:$A999)=A2,year(Sales!$A$2:$A999)=B2) -> 1171.63 | D2: =Sumproduct('Amazon Royalties'!$E$2:$E999,month('Amazon Royalties'!$B$2:$B999)=A2,year('Amazon Royalties'!$B$2:$B999)=B2) -> 78.357601 | E2: =Sumproduct(Sales!$K$2:$K999,month(Sales!$A$2:$A999)=A2,year(Sales!$A$2:$A999)=B2) -> 750 | F2: =Sumproduct(Expenses!$B$2:$B999,Month(Expenses!$A$2:$A999)=A2,year(Expenses!$A$2:$A999)=B2) -> 59.31 | G2: =Sumproduct('Staff Salaries'!$B$3:$B999,month('Staff Salaries'!$A$3:$A999)=$A2,year('Staff Salaries'!$A$3:$A999)=$B2) -> 300 | H2: =IFERROR(__xludf.DUMMYFUNCTION("sumproduct(importrange(""https://docs.google.com/spreadsheets/d/15CJ-h55pYD1KSEfDJoQc5rhrr0QtLCfpr6KnyxjMee4/edit#gid=71971023"",""Expired!E2:E""),Month(importrange(""https://docs.google.com/spreadsheets/d/15CJ-h55pYD1KSEfDJoQc5rhrr0QtLCfpr6KnyxjMee4/edit"&"#gid=71971023"",""Expired!a2:a""))=A2,year(importrange(""https://docs.google.com/spreadsheets/d/15CJ-h55pYD1KSEfDJoQc5rhrr0QtLCfpr6KnyxjMee4/edit#gid=71971023"",""Expired!a2:a""))=B2)"),0.0) -> 0 | I2: =sumproduct('Profit Distributions'!$B$2:$B999,Year('Profit Distributions'!$A$2:$A999)=B2,Month('Profit Distributions'!$A$2:$A999)=A2,'Profit Distributions'!$C$2:$C999<>"Savings") -> 0 | J2: =sumproduct('Profit Distributions'!$B$2:$B999,Year('Profit Distributions'!$A$2:$A999)=B2,Month('Profit Distributions'!$A$2:$A999)=A2,'Profit Distributions'!$C$2:$C999="Savings") -> 0 | K2: =C2+D2-F2-G2-E2+H2 -> 140.6776 | L2: =K2-J2 -> 140.6776 | M2: =L2-I2 -> 140.6776 | O2: =IFERROR(__xludf.DUMMYFUNCTION("INDEX(M:M, MAX(FILTER(ROW(M:M), ISNUMBER(M:M))))+'Profit Distributions'!$G$3+'Staff Total'!$D$2"),-4985.266742111924) -> -4985.2667
A3: 8 | B3: 2022 | C3: =Sumproduct(Sales!$F$2:$F999,month(Sales!$A$2:$A999)=A3,year(Sales!$A$2:$A999)=B3) -> 1576.13 | D3: =Sumproduct('Amazon Royalties'!$E$2:$E999,month('Amazon Royalties'!$B$2:$B999)=A3,year('Amazon Royalties'!$B$2:$B999)=B3) -> 67.87038 | E3: =Sumproduct(Sales!$K$2:$K999,month(Sales!$A$2:$A999)=A3,year(Sales!$A$2:$A999)=B3) -> 945 | F3: =Sumproduct(Expenses!$B$2:$B999,Month(Expenses!$A$2:$A999)=A3,year(Expenses!$A$2:$A999)=B3) -> 298.52 | G3: =Sumproduct('Staff Salaries'!$B$3:$B999,month('Staff Salaries'!$A$3:$A999)=$A3,year('Staff Salaries'!$A$3:$A999)=$B3) -> 300 | H3: =IFERROR(__xludf.DUMMYFUNCTION("sumproduct(importrange(""https://docs.google.com/spreadsheets/d/15CJ-h55pYD1KSEfDJoQc5rhrr0QtLCfpr6KnyxjMee4/edit#gid=71971023"",""Expired!E2:E""),Month(importrange(""https://docs.google.com/spreadsheets/d/15CJ-h55pYD1KSEfDJoQc5rhrr0QtLCfpr6KnyxjMee4/edit"&"#gid=71971023"",""Expired!a2:a""))=A3,year(importrange(""https://docs.google.com/spreadsheets/d/15CJ-h55pYD1KSEfDJoQc5rhrr0QtLCfpr6KnyxjMee4/edit#gid=71971023"",""Expired!a2:a""))=B3)"),0.0) -> 0 | I3: =sumproduct('Profit Distributions'!$B$2:$B999,Year('Profit Distributions'!$A$2:$A999)=B3,Month('Profit Distributions'!$A$2:$A999)=A3,'Profit Distributions'!$C$2:$C999<>"Savings") -> 0 | J3: =sumproduct('Profit Distributions'!$B$2:$B999,Year('Profit Distributions'!$A$2:$A999)=B3,Month('Profit Distributions'!$A$2:$A999)=A3,'Profit Distributions'!$C$2:$C999="Savings") -> 0 | K3: =C3+D3-F3-G3-E3+H3 -> 100.48038 | L3: =K3-J3 -> 100.48038 | M3: =L3+M2-I3 -> 241.15798
A4: 9 | B4: 2022 | C4: =Sumproduct(Sales!$F$2:$F999,month(Sales!$A$2:$A999)=A4,year(Sales!$A$2:$A999)=B4) -> 1312.72 | D4: =Sumproduct('Amazon Royalties'!$E$2:$E999,month('Amazon Royalties'!$B$2:$B999)=A4,year('Amazon Royalties'!$B$2:$B999)=B4) -> 72.406828 | E4: =Sumproduct(Sales!$K$2:$K999,month(Sales!$A$2:$A999)=A4,year(Sales!$A$2:$A999)=B4) -> 855 | F4: =Sumproduct(Expenses!$B$2:$B999,Month(Expenses!$A$2:$A999)=A4,year(Expenses!$A$2:$A999)=B4) -> 228.3 | G4: =Sumproduct('Staff Salaries'!$B$3:$B999,month('Staff Salaries'!$A$3:$A999)=$A4,year('Staff Salaries'!$A$3:$A999)=$B4) -> 300 | H4: =IFERROR(__xludf.DUMMYFUNCTION("sumproduct(importrange(""https://docs.google.com/spreadsheets/d/15CJ-h55pYD1KSEfDJoQc5rhrr0QtLCfpr6KnyxjMee4/edit#gid=71971023"",""Expired!E2:E""),Month(importrange(""https://docs.google.com/spreadsheets/d/15CJ-h55pYD1KSEfDJoQc5rhrr0QtLCfpr6KnyxjMee4/edit"&"#gid=71971023"",""Expired!a2:a""))=A4,year(importrange(""https://docs.google.com/spreadsheets/d/15CJ-h55pYD1KSEfDJoQc5rhrr0QtLCfpr6KnyxjMee4/edit#gid=71971023"",""Expired!a2:a""))=B4)"),0.0) -> 0 | I4: =sumproduct('Profit Distributions'!$B$2:$B999,Year('Profit Distributions'!$A$2:$A999)=B4,Month('Profit Distributions'!$A$2:$A999)=A4,'Profit Distributions'!$C$2:$C999<>"Savings") -> 0 | J4: =sumproduct('Profit Distributions'!$B$2:$B999,Year('Profit Distributions'!$A$2:$A999)=B4,Month('Profit Distributions'!$A$2:$A999)=A4,'Profit Distributions'!$C$2:$C999="Savings") -> 0 | K4: =C4+D4-F4-G4-E4+H4 -> 1.826828 | L4: =K4-J4 -> 1.826828 | M4: =L4+M3-I4 -> 242.98481
A5: 10 | B5: 2022 | C5: =Sumproduct(Sales!$F$2:$F999,month(Sales!$A$2:$A999)=A5,year(Sales!$A$2:$A999)=B5) -> 1510.96 | D5: =Sumproduct('Amazon Royalties'!$E$2:$E999,month('Amazon Royalties'!$B$2:$B999)=A5,year('Amazon Royalties'!$B$2:$B999)=B5) -> 79.820326 | E5: =Sumproduct(Sales!$K$2:$K999,month(Sales!$A$2:$A999)=A5,year(Sales!$A$2:$A999)=B5) -> 1020 | F5: =Sumproduct(Expenses!$B$2:$B999,Month(Expenses!$A$2:$A999)=A5,year(Expenses!$A$2:$A999)=B5) -> 217.4 | G5: =Sumproduct('Staff Salaries'!$B$3:$B999,month('Staff Salaries'!$A$3:$A999)=$A5,year('Staff Salaries'!$A$3:$A999)=$B5) -> 300 | H5: =IFERROR(__xludf.DUMMYFUNCTION("sumproduct(importrange(""https://docs.google.com/spreadsheets/d/15CJ-h55pYD1KSEfDJoQc5rhrr0QtLCfpr6KnyxjMee4/edit#gid=71971023"",""Expired!E2:E""),Month(importrange(""https://docs.google.com/spreadsheets/d/15CJ-h55pYD1KSEfDJoQc5rhrr0QtLCfpr6KnyxjMee4/edit"&"#gid=71971023"",""Expired!a2:a""))=A5,year(importrange(""https://docs.google.com/spreadsheets/d/15CJ-h55pYD1KSEfDJoQc5rhrr0QtLCfpr6KnyxjMee4/edit#gid=71971023"",""Expired!a2:a""))=B5)"),0.0) -> 0 | I5: =sumproduct('Profit Distributions'!$B$2:$B999,Year('Profit Distributions'!$A$2:$A999)=B5,Month('Profit Distributions'!$A$2:$A999)=A5,'Profit Distributions'!$C$2:$C999<>"Savings") -> 0 | J5: =sumproduct('Profit Distributions'!$B$2:$B999,Year('Profit Distributions'!$A$2:$A999)=B5,Month('Profit Distributions'!$A$2:$A999)=A5,'Profit Distributions'!$C$2:$C999="Savings") -> 0 | K5: =C5+D5-F5-G5-E5+H5 -> 53.380326 | L5: =K5-J5 -> 53.380326 | M5: =L5+M4-I5 -> 296.36513
A6: 11 | B6: 2022 | C6: =Sumproduct(Sales!$F$2:$F999,month(Sales!$A$2:$A999)=A6,year(Sales!$A$2:$A999)=B6) -> 1077.53 | D6: =Sumproduct('Amazon Royalties'!$E$2:$E999,month('Amazon Royalties'!$B$2:$B999)=A6,year('Amazon Royalties'!$B$2:$B999)=B6) -> 82.575785 | E6: =Sumproduct(Sales!$K$2:$K999,month(Sales!$A$2:$A999)=A6,year(Sales!$A$2:$A999)=B6) -> 570 | F6: =Sumproduct(Expenses!$B$2:$B999,Month(Expenses!$A$2:$A999)=A6,year(Expenses!$A$2:$A999)=B6) -> 175.97 | G6: =Sumproduct('Staff Salaries'!$B$3:$B999,month('Staff Salaries'!$A$3:$A999)=$A6,year('Staff Salaries'!$A$3:$A999)=$B6) -> 300 | H6: =IFERROR(__xludf.DUMMYFUNCTION("sumproduct(importrange(""https://docs.google.com/spreadsheets/d/15CJ-h55pYD1KSEfDJoQc5rhrr0QtLCfpr6KnyxjMee4/edit#gid=71971023"",""Expired!E2:E""),Month(importrange(""https://docs.google.com/spreadsheets/d/15CJ-h55pYD1KSEfDJoQc5rhrr0QtLCfpr6KnyxjMee4/edit"&"#gid=71971023"",""Expired!a2:a""))=A6,year(importrange(""https://docs.google.com/spreadsheets/d/15CJ-h55pYD1KSEfDJoQc5rhrr0QtLCfpr6KnyxjMee4/edit#gid=71971023"",""Expired!a2:a""))=B6)"),0.0) -> 0 | I6: =sumproduct('Profit Distributions'!$B$2:$B999,Year('Profit Distributions'!$A$2:$A999)=B6,Month('Profit Distributions'!$A$2:$A999)=A6,'Profit Distributions'!$C$2:$C999<>"Savings") -> 0 | J6: =sumproduct('Profit Distributions'!$B$2:$B999,Year('Profit Distributions'!$A$2:$A999)=B6,Month('Profit Distributions'!$A$2:$A999)=A6,'Profit Distributions'!$C$2:$C999="Savings") -> 0 | K6: =C6+D6-F6-G6-E6+H6 -> 114.13578 | L6: =K6-J6 -> 114.13578 | M6: =L6+M5-I6 -> 410.50092
A7: 12 | B7: 2022 | C7: =Sumproduct(Sales!$F$2:$F999,month(Sales!$A$2:$A999)=A7,year(Sales!$A$2:$A999)=B7) -> 1433.11 | D7: =Sumproduct('Amazon Royalties'!$E$2:$E999,month('Amazon Royalties'!$B$2:$B999)=A7,year('Amazon Royalties'!$B$2:$B999)=B7) -> 109.97503 | E7: =Sumproduct(Sales!$K$2:$K999,month(Sales!$A$2:$A999)=A7,year(Sales!$A$2:$A999)=B7) -> 1140 | F7: =Sumproduct(Expenses!$B$2:$B999,Month(Expenses!$A$2:$A999)=A7,year(Expenses!$A$2:$A999)=B7) -> 577.77 | G7: =Sumproduct('Staff Salaries'!$B$3:$B999,month('Staff Salaries'!$A$3:$A999)=$A7,year('Staff Salaries'!$A$3:$A999)=$B7) -> 300 | H7: =IFERROR(__xludf.DUMMYFUNCTION("sumproduct(importrange(""https://docs.google.com/spreadsheets/d/15CJ-h55pYD1KSEfDJoQc5rhrr0QtLCfpr6KnyxjMee4/edit#gid=71971023"",""Expired!E2:E""),Month(importrange(""https://docs.google.com/spreadsheets/d/15CJ-h55pYD1KSEfDJoQc5rhrr0QtLCfpr6KnyxjMee4/edit"&"#gid=71971023"",""Expired!a2:a""))=A7,year(importrange(""https://docs.google.com/spreadsheets/d/15CJ-h55pYD1KSEfDJoQc5rhrr0QtLCfpr6KnyxjMee4/edit#gid=71971023"",""Expired!a2:a""))=B7)"),0.0) -> 0 | I7: =sumproduct('Profit Distributions'!$B$2:$B999,Year('Profit Distributions'!$A$2:$A999)=B7,Month('Profit Distributions'!$A$2:$A999)=A7,'Profit Distributions'!$C$2:$C999<>"Savings") -> 0 | J7: =sumproduct('Profit Distributions'!$B$2:$B999,Year('Profit Distributions'!$A$2:$A999)=B7,Month('Profit Distributions'!$A$2:$A999)=A7,'Profit Distributions'!$C$2:$C999="Savings") -> 0 | K7: =C7+D7-F7-G7-E7+H7 -> -474.68497 | L7: =K7-J7 -> -474.68497 | M7: =L7+M6-I7 -> -64.184052
A8: 1 | B8: 2023 | C8: =Sumproduct(Sales!$F$2:$F999,month(Sales!$A$2:$A999)=A8,year(Sales!$A$2:$A999)=B8) -> 4994.92 | D8: =Sumproduct('Amazon Royalties'!$E$2:$E999,month('Amazon Royalties'!$B$2:$B999)=A8,year('Amazon Royalties'!$B$2:$B999)=B8) -> 49.221648 | E8: =Sumproduct(Sales!$K$2:$K999,month(Sales!$A$2:$A999)=A8,year(Sales!$A$2:$A999)=B8) -> 2415 | F8: =Sumproduct(Expenses!$B$2:$B999,Month(Expenses!$A$2:$A999)=A8,year(Expenses!$A$2:$A999)=B8) -> 222.7 | G8: =Sumproduct('Staff Salaries'!$B$3:$B999,month('Staff Salaries'!$A$3:$A999)=$A8,year('Staff Salaries'!$A$3:$A999)=$B8) -> 300 | H8: =IFERROR(__xludf.DUMMYFUNCTION("sumproduct(importrange(""https://docs.google.com/spreadsheets/d/15CJ-h55pYD1KSEfDJoQc5rhrr0QtLCfpr6KnyxjMee4/edit#gid=71971023"",""Expired!E2:E""),Month(importrange(""https://docs.google.com/spreadsheets/d/15CJ-h55pYD1KSEfDJoQc5rhrr0QtLCfpr6KnyxjMee4/edit"&"#gid=71971023"",""Expired!a2:a""))=A8,year(importrange(""https://docs.google.com/spreadsheets/d/15CJ-h55pYD1KSEfDJoQc5rhrr0QtLCfpr6KnyxjMee4/edit#gid=71971023"",""Expired!a2:a""))=B8)"),0.0) -> 0 | I8: =sumproduct('Profit Distributions'!$B$2:$B999,Year('Profit Distributions'!$A$2:$A999)=B8,Month('Profit Distributions'!$A$2:$A999)=A8,'Profit Distributions'!$C$2:$C999<>"Savings") -> 0 | J8: =sumproduct('Profit Distributions'!$B$2:$B999,Year('Profit Distributions'!$A$2:$A999)=B8,Month('Profit Distributions'!$A$2:$A999)=A8,'Profit Distributions'!$C$2:$C999="Savings") -> 0 | K8: =C8+D8-F8-G8-E8+H8 -> 2106.4416 | L8: =K8-J8 -> 2106.4416 | M8: =L8+M7-I8 -> 2042.2576
A9: 2 | B9: 2023 | C9: =Sumproduct(Sales!$F$2:$F999,month(Sales!$A$2:$A999)=A9,year(Sales!$A$2:$A999)=B9) -> 3661.85 | D9: =Sumproduct('Amazon Royalties'!$E$2:$E999,month('Amazon Royalties'!$B$2:$B999)=A9,year('Amazon Royalties'!$B$2:$B999)=B9) -> 66.627678 | E9: =Sumproduct(Sales!$K$2:$K999,month(Sales!$A$2:$A999)=A9,year(Sales!$A$2:$A999)=B9) -> 1800 | F9: =Sumproduct(Expenses!$B$2:$B999,Month(Expenses!$A$2:$A999)=A9,year(Expenses!$A$2:$A999)=B9) -> 171.16 | G9: =Sumproduct('Staff Salaries'!$B$3:$B999,month('Staff Salaries'!$A$3:$A999)=$A9,year('Staff Salaries'!$A$3:$A999)=$B9) -> 300 | H9: =IFERROR(__xludf.DUMMYFUNCTION("sumproduct(importrange(""https://docs.google.com/spreadsheets/d/15CJ-h55pYD1KSEfDJoQc5rhrr0QtLCfpr6KnyxjMee4/edit#gid=71971023"",""Expired!E2:E""),Month(importrange(""https://docs.google.com/spreadsheets/d/15CJ-h55pYD1KSEfDJoQc5rhrr0QtLCfpr6KnyxjMee4/edit"&"#gid=71971023"",""Expired!a2:a""))=A9,year(importrange(""https://docs.google.com/spreadsheets/d/15CJ-h55pYD1KSEfDJoQc5rhrr0QtLCfpr6KnyxjMee4/edit#gid=71971023"",""Expired!a2:a""))=B9)"),0.0) -> 0 | I9: =sumproduct('Profit Distributions'!$B$2:$B999,Year('Profit Distributions'!$A$2:$A999)=B9,Month('Profit Distributions'!$A$2:$A999)=A9,'Profit Distributions'!$C$2:$C999<>"Savings") -> 1100 | J9: =sumproduct('Profit Distributions'!$B$2:$B999,Year('Profit Distributions'!$A$2:$A999)=B9,Month('Profit Distributions'!$A$2:$A999)=A9,'Profit Distributions'!$C$2:$C999="Savings") -> 0 | K9: =C9+D9-F9-G9-E9+H9 -> 1457.3177 | L9: =K9-J9 -> 1457.3177 | M9: =L9+M8-I9 -> 2399.5753
A10: 3 | B10: 2023 | C10: =Sumproduct(Sales!$F$2:$F999,month(Sales!$A$2:$A999)=A10,year(Sales!$A$2:$A999)=B10) -> 2499.48 | D10: =Sumproduct('Amazon Royalties'!$E$2:$E999,month('Amazon Royalties'!$B$2:$B999)=A10,year('Amazon Royalties'!$B$2:$B999)=B10) -> 170.29945 | E10: =Sumproduct(Sales!$K$2:$K999,month(Sales!$A$2:$A999)=A10,year(Sales!$A$2:$A999)=B10) -> 1500 | F10: =Sumproduct(Expenses!$B$2:$B999,Month(Expenses!$A$2:$A999)=A10,year(Expenses!$A$2:$A999)=B10) -> 303.93 | G10: =Sumproduct('Staff Salaries'!$B$3:$B999,month('Staff Salaries'!$A$3:$A999)=$A10,year('Staff Salaries'!$A$3:$A999)=$B10) -> 300 | H10: =IFERROR(__xludf.DUMMYFUNCTION("sumproduct(importrange(""https://docs.google.com/spreadsheets/d/15CJ-h55pYD1KSEfDJoQc5rhrr0QtLCfpr6KnyxjMee4/edit#gid=71971023"",""Expired!E2:E""),Month(importrange(""https://docs.google.com/spreadsheets/d/15CJ-h55pYD1KSEfDJoQc5rhrr0QtLCfpr6KnyxjMee4/edit"&"#gid=71971023"",""Expired!a2:a""))=A10,year(importrange(""https://docs.google.com/spreadsheets/d/15CJ-h55pYD1KSEfDJoQc5rhrr0QtLCfpr6KnyxjMee4/edit#gid=71971023"",""Expired!a2:a""))=B10)"),0.0) -> 0 | I10: =sumproduct('Profit Distributions'!$B$2:$B999,Year('Profit Distributions'!$A$2:$A999)=B10,Month('Profit Distributions'!$A$2:$A999)=A10,'Profit Distributions'!$C$2:$C999<>"Savings") -> 1100 | J10: =sumproduct('Profit Distributions'!$B$2:$B999,Year('Profit Distributions'!$A$2:$A999)=B10,Month('Profit Distributions'!$A$2:$A999)=A10,'Profit Distributions'!$C$2:$C999="Savings") -> 0 | K10: =C10+D10-F10-G10-E10+H10 -> 565.84945 | L10: =K10-J10 -> 565.84945 | M10: =L10+M9-I10 -> 1865.4247
A11: 4 | B11: 2023 | C11: =Sumproduct(Sales!$F$2:$F999,month(Sales!$A$2:$A999)=A11,year(Sales!$A$2:$A999)=B11) -> 2657.56 | D11: =Sumproduct('Amazon Royalties'!$E$2:$E999,month('Amazon Royalties'!$B$2:$B999)=A11,year('Amazon Royalties'!$B$2:$B999)=B11) -> 98.90229 | E11: =Sumproduct(Sales!$K$2:$K999,month(Sales!$A$2:$A999)=A11,year(Sales!$A$2:$A999)=B11) -> 1800 | F11: =Sumproduct(Expenses!$B$2:$B999,Month(Expenses!$A$2:$A999)=A11,year(Expenses!$A$2:$A999)=B11) -> 178.3 | G11: =Sumproduct('Staff Salaries'!$B$3:$B999,month('Staff Salaries'!$A$3:$A999)=$A11,year('Staff Salaries'!$A$3:$A999)=$B11) -> 300 | H11: =IFERROR(__xludf.DUMMYFUNCTION("sumproduct(importrange(""https://docs.google.com/spreadsheets/d/15CJ-h55pYD1KSEfDJoQc5rhrr0QtLCfpr6KnyxjMee4/edit#gid=71971023"",""Expired!E2:E""),Month(importrange(""https://docs.google.com/spreadsheets/d/15CJ-h55pYD1KSEfDJoQc5rhrr0QtLCfpr6KnyxjMee4/edit"&"#gid=71971023"",""Expired!a2:a""))=A11,year(importrange(""https://docs.google.com/spreadsheets/d/15CJ-h55pYD1KSEfDJoQc5rhrr0QtLCfpr6KnyxjMee4/edit#gid=71971023"",""Expired!a2:a""))=B11)"),0.0) -> 0 | I11: =sumproduct('Profit Distributions'!$B$2:$B999,Year('Profit Distributions'!$A$2:$A999)=B11,Month('Profit Distributions'!$A$2:$A999)=A11,'Profit Distributions'!$C$2:$C999<>"Savings") -> 0 | J11: =sumproduct('Profit Distributions'!$B$2:$B999,Year('Profit Distributions'!$A$2:$A999)=B11,Month('Profit Distributions'!$A$2:$A999)=A11,'Profit Distributions'!$C$2:$C999="Savings") -> 0 | K11: =C11+D11-F11-G11-E11+H11 -> 478.16229 | L11: =K11-J11 -> 478.16229 | M11: =L11+M10-I11 -> 2343.587
A12: 5 | B12: 2023 | C12: =Sumproduct(Sales!$F$2:$F999,month(Sales!$A$2:$A999)=A12,year(Sales!$A$2:$A999)=B12) -> 2633.81 | D12: =Sumproduct('Amazon Royalties'!$E$2:$E999,month('Amazon Royalties'!$B$2:$B999)=A12,year('Amazon Royalties'!$B$2:$B999)=B12) -> 75.94143 | E12: =Sumproduct(Sales!$K$2:$K999,month(Sales!$A$2:$A999)=A12,year(Sales!$A$2:$A999)=B12) -> 1845 | F12: =Sumproduct(Expenses!$B$2:$B999,Month(Expenses!$A$2:$A999)=A12,year(Expenses!$A$2:$A999)=B12) -> 351.75 | G12: =Sumproduct('Staff Salaries'!$B$3:$B999,month('Staff Salaries'!$A$3:$A999)=$A12,year('Staff Salaries'!$A$3:$A999)=$B12) -> 300 | H12: =IFERROR(__xludf.DUMMYFUNCTION("sumproduct(importrange(""https://docs.google.com/spreadsheets/d/15CJ-h55pYD1KSEfDJoQc5rhrr0QtLCfpr6KnyxjMee4/edit#gid=71971023"",""Expired!E2:E""),Month(importrange(""https://docs.google.com/spreadsheets/d/15CJ-h55pYD1KSEfDJoQc5rhrr0QtLCfpr6KnyxjMee4/edit"&"#gid=71971023"",""Expired!a2:a""))=A12,year(importrange(""https://docs.google.com/spreadsheets/d/15CJ-h55pYD1KSEfDJoQc5rhrr0QtLCfpr6KnyxjMee4/edit#gid=71971023"",""Expired!a2:a""))=B12)"),90.0) -> 90 | I12: =sumproduct('Profit Distributions'!$B$2:$B999,Year('Profit Distributions'!$A$2:$A999)=B12,Month('Profit Distributions'!$A$2:$A999)=A12,'Profit Distributions'!$C$2:$C999<>"Savings") -> 1400 | J12: =sumproduct('Profit Distributions'!$B$2:$B999,Year('Profit Distributions'!$A$2:$A999)=B12,Month('Profit Distributions'!$A$2:$A999)=A12,'Profit Distributions'!$C$2:$C999="Savings") -> 0 | K12: =C12+D12-F12-G12-E12+H12 -> 303.00143 | L12: =K12-J12 -> 303.00143 | M12: =L12+M11-I12 -> 1246.5884
A13: 6 | B13: 2023 | C13: =Sumproduct(Sales!$F$2:$F999,month(Sales!$A$2:$A999)=A13,year(Sales!$A$2:$A999)=B13) -> 1009.09 | D13: =Sumproduct('Amazon Royalties'!$E$2:$E999,month('Amazon Royalties'!$B$2:$B999)=A13,year('Amazon Royalties'!$B$2:$B999)=B13) -> 103.64184 | E13: =Sumproduct(Sales!$K$2:$K999,month(Sales!$A$2:$A999)=A13,year(Sales!$A$2:$A999)=B13) -> 255 | F13: =Sumproduct(Expenses!$B$2:$B999,Month(Expenses!$A$2:$A999)=A13,year(Expenses!$A$2:$A999)=B13) -> 211.7 | G13: =Sumproduct('Staff Salaries'!$B$3:$B999,month('Staff Salaries'!$A$3:$A999)=$A13,year('Staff Salaries'!$A$3:$A999)=$B13) -> 300 | H13: =IFERROR(__xludf.DUMMYFUNCTION("sumproduct(importrange(""https://docs.google.com/spreadsheets/d/15CJ-h55pYD1KSEfDJoQc5rhrr0QtLCfpr6KnyxjMee4/edit#gid=71971023"",""Expired!E2:E""),Month(importrange(""https://docs.google.com/spreadsheets/d/15CJ-h55pYD1KSEfDJoQc5rhrr0QtLCfpr6KnyxjMee4/edit"&"#gid=71971023"",""Expired!a2:a""))=A13,year(importrange(""https://docs.google.com/spreadsheets/d/15CJ-h55pYD1KSEfDJoQc5rhrr0QtLCfpr6KnyxjMee4/edit#gid=71971023"",""Expired!a2:a""))=B13)"),0.0) -> 0 | I13: =sumproduct('Profit Distributions'!$B$2:$B999,Year('Profit Distributions'!$A$2:$A999)=B13,Month('Profit Distributions'!$A$2:$A999)=A13,'Profit Distributions'!$C$2:$C999<>"Savings") -> 0 | J13: =sumproduct('Profit Distributions'!$B$2:$B999,Year('Profit Distributions'!$A$2:$A999)=B13,Month('Profit Distributions'!$A$2:$A999)=A13,'Profit Distributions'!$C$2:$C999="Savings") -> 0 | K13: =C13+D13-F13-G13-E13+H13 -> 346.03184 | L13: =K13-J13 -> 346.03184 | M13: =L13+M12-I13 -> 1592.6203
A14: 7 | B14: 2023 | C14: =Sumproduct(Sales!$F$2:$F999,month(Sales!$A$2:$A999)=A14,year(Sales!$A$2:$A999)=B14) -> 2546.8161 | D14: =Sumproduct('Amazon Royalties'!$E$2:$E999,month('Amazon Royalties'!$B$2:$B999)=A14,year('Amazon Royalties'!$B$2:$B999)=B14) -> 83.72371 | E14: =Sumproduct(Sales!$K$2:$K999,month(Sales!$A$2:$A999)=A14,year(Sales!$A$2:$A999)=B14) -> 240 | F14: =Sumproduct(Expenses!$B$2:$B999,Month(Expenses!$A$2:$A999)=A14,year(Expenses!$A$2:$A999)=B14) -> 233.48 | G14: =Sumproduct('Staff Salaries'!$B$3:$B999,month('Staff Salaries'!$A$3:$A999)=$A14,year('Staff Salaries'!$A$3:$A999)=$B14) -> 300 | H14: =IFERROR(__xludf.DUMMYFUNCTION("sumproduct(importrange(""https://docs.google.com/spreadsheets/d/15CJ-h55pYD1KSEfDJoQc5rhrr0QtLCfpr6KnyxjMee4/edit#gid=71971023"",""Expired!E2:E""),Month(importrange(""https://docs.google.com/spreadsheets/d/15CJ-h55pYD1KSEfDJoQc5rhrr0QtLCfpr6KnyxjMee4/edit"&"#gid=71971023"",""Expired!a2:a""))=A14,year(importrange(""https://docs.google.com/spreadsheets/d/15CJ-h55pYD1KSEfDJoQc5rhrr0QtLCfpr6KnyxjMee4/edit#gid=71971023"",""Expired!a2:a""))=B14)"),0.0) -> 0 | I14: =sumproduct('Profit Distributions'!$B$2:$B999,Year('Profit Distributions'!$A$2:$A999)=B14,Month('Profit Distributions'!$A$2:$A999)=A14,'Profit Distributions'!$C$2:$C999<>"Savings") -> 274 | J14: =sumproduct('Profit Distributions'!$B$2:$B999,Year('Profit Distributions'!$A$2:$A999)=B14,Month('Profit Distributions'!$A$2:$A999)=A14,'Profit Distributions'!$C$2:$C999="Savings") -> 0 | K14: =C14+D14-F14-G14-E14+H14 -> 1857.0598 | L14: =K14-J14 -> 1857.0598 | M14: =L14+M13-I14 -> 3175.6801
A15: 8 | B15: 2023 | C15: =Sumproduct(Sales!$F$2:$F999,month(Sales!$A$2:$A999)=A15,year(Sales!$A$2:$A999)=B15) -> 3586.524 | D15: =Sumproduct('Amazon Royalties'!$E$2:$E999,month('Amazon Royalties'!$B$2:$B999)=A15,year('Amazon Royalties'!$B$2:$B999)=B15) -> 81.022032 | E15: ='Teacher Salaries'!V16 -> 971.25 | F15: =Sumproduct(Expenses!$B$2:$B999,Month(Expenses!$A$2:$A999)=A15,year(Expenses!$A$2:$A999)=B15) -> 420.98 | G15: =Sumproduct('Staff Salaries'!$B$3:$B999,month('Staff Salaries'!$A$3:$A999)=$A15,year('Staff Salaries'!$A$3:$A999)=$B15) -> 0 | H15: =IFERROR(__xludf.DUMMYFUNCTION("sumproduct(importrange(""https://docs.google.com/spreadsheets/d/15CJ-h55pYD1KSEfDJoQc5rhrr0QtLCfpr6KnyxjMee4/edit#gid=71971023"",""Expired!E2:E""),Month(importrange(""https://docs.google.com/spreadsheets/d/15CJ-h55pYD1KSEfDJoQc5rhrr0QtLCfpr6KnyxjMee4/edit"&"#gid=71971023"",""Expired!a2:a""))=A15,year(importrange(""https://docs.google.com/spreadsheets/d/15CJ-h55pYD1KSEfDJoQc5rhrr0QtLCfpr6KnyxjMee4/edit#gid=71971023"",""Expired!a2:a""))=B15)"),405.0) -> 405 | I15: =sumproduct('Profit Distributions'!$B$2:$B999,Year('Profit Distributions'!$A$2:$A999)=B15,Month('Profit Distributions'!$A$2:$A999)=A15,'Profit Distributions'!$C$2:$C999<>"Savings") -> 1800 | J15: =sumproduct('Profit Distributions'!$B$2:$B999,Year('Profit Distributions'!$A$2:$A999)=B15,Month('Profit Distributions'!$A$2:$A999)=A15,'Profit Distributions'!$C$2:$C999="Savings") -> 1600 | K15: =C15+D15-F15-G15-E15+H15 -> 2680.316 | L15: =K15-J15 -> 1080.316 | M15: =L15+M14-I15 -> 2455.9962
A16: 9 | B16: 2023 | C16: =Sumproduct(Sales!$F$2:$F999,month(Sales!$A$2:$A999)=A16,year(Sales!$A$2:$A999)=B16) -> 2256.8178 | D16: =Sumproduct('Amazon Royalties'!$E$2:$E999,month('Amazon Royalties'!$B$2:$B999)=A16,year('Amazon Royalties'!$B$2:$B999)=B16) -> 107.45421 | E16: ='Teacher Salaries'!V17 -> 1600 | F16: =Sumproduct(Expenses!$B$2:$B999,Month(Expenses!$A$2:$A999)=A16,year(Expenses!$A$2:$A999)=B16) -> 226.46 | G16: =Sumproduct('Staff Salaries'!$B$3:$B999,month('Staff Salaries'!$A$3:$A999)=$A16,year('Staff Salaries'!$A$3:$A999)=$B16) -> 0 | H16: =IFERROR(__xludf.DUMMYFUNCTION("sumproduct(importrange(""https://docs.google.com/spreadsheets/d/15CJ-h55pYD1KSEfDJoQc5rhrr0QtLCfpr6KnyxjMee4/edit#gid=71971023"",""Expired!E2:E""),Month(importrange(""https://docs.google.com/spreadsheets/d/15CJ-h55pYD1KSEfDJoQc5rhrr0QtLCfpr6KnyxjMee4/edit"&"#gid=71971023"",""Expired!a2:a""))=A16,year(importrange(""https://docs.google.com/spreadsheets/d/15CJ-h55pYD1KSEfDJoQc5rhrr0QtLCfpr6KnyxjMee4/edit#gid=71971023"",""Expired!a2:a""))=B16)"),0.0) -> 0 | I16: =sumproduct('Profit Distributions'!$B$2:$B999,Year('Profit Distributions'!$A$2:$A999)=B16,Month('Profit Distributions'!$A$2:$A999)=A16,'Profit Distributions'!$C$2:$C999<>"Savings") -> 2674 | J16: =sumproduct('Profit Distributions'!$B$2:$B999,Year('Profit Distributions'!$A$2:$A999)=B16,Month('Profit Distributions'!$A$2:$A999)=A16,'Profit Distributions'!$C$2:$C999="Savings") -> 0 | K16: =C16+D16-F16-G16-E16+H16 -> 537.81201 | L16: =K16-J16 -> 537.81201 | M16: =L16+M15-I16 -> 319.80818
A17: 10 | B17: 2023 | C17: =Sumproduct(Sales!$F$2:$F999,month(Sales!$A$2:$A999)=A17,year(Sales!$A$2:$A999)=B17) -> 3826.5466 | D17: =Sumproduct('Amazon Royalties'!$E$2:$E999,month('Amazon Royalties'!$B$2:$B999)=A17,year('Amazon Royalties'!$B$2:$B999)=B17) -> 92.757525 | E17: ='Teacher Salaries'!V18 -> 1600 | F17: =Sumproduct(Expenses!$B$2:$B999,Month(Expenses!$A$2:$A999)=A17,year(Expenses!$A$2:$A999)=B17) -> 205.66 | G17: =Sumproduct('Staff Salaries'!$B$3:$B999,month('Staff Salaries'!$A$3:$A999)=$A17,year('Staff Salaries'!$A$3:$A999)=$B17) -> 0 | H17: =IFERROR(__xludf.DUMMYFUNCTION("sumproduct(importrange(""https://docs.google.com/spreadsheets/d/15CJ-h55pYD1KSEfDJoQc5rhrr0QtLCfpr6KnyxjMee4/edit#gid=71971023"",""Expired!E2:E""),Month(importrange(""https://docs.google.com/spreadsheets/d/15CJ-h55pYD1KSEfDJoQc5rhrr0QtLCfpr6KnyxjMee4/edit"&"#gid=71971023"",""Expired!a2:a""))=A17,year(importrange(""https://docs.google.com/spreadsheets/d/15CJ-h55pYD1KSEfDJoQc5rhrr0QtLCfpr6KnyxjMee4/edit#gid=71971023"",""Expired!a2:a""))=B17)"),0.0) -> 0 | I17: =sumproduct('Profit Distributions'!$B$2:$B999,Year('Profit Distributions'!$A$2:$A999)=B17,Month('Profit Distributions'!$A$2:$A999)=A17,'Profit Distributions'!$C$2:$C999<>"Savings") -> 0 | J17: =sumproduct('Profit Distributions'!$B$2:$B999,Year('Profit Distributions'!$A$2:$A999)=B17,Month('Profit Distributions'!$A$2:$A999)=A17,'Profit Distributions'!$C$2:$C999="Savings") -> 0 | K17: =C17+D17-F17-G17-E17+H17 -> 2113.6442 | L17: =K17-J17 -> 2113.6442 | M17: =L17+M16-I17 -> 2433.4523
A18: 11 | B18: 2023 | C18: =Sumproduct(Sales!$F$2:$F999,month(Sales!$A$2:$A999)=A18,year(Sales!$A$2:$A999)=B18) -> 3221.9333 | D18: =Sumproduct('Amazon Royalties'!$E$2:$E999,month('Amazon Royalties'!$B$2:$B999)=A18,year('Amazon Royalties'!$B$2:$B999)=B18) -> 99.983457 | E18: ='Teacher Salaries'!V19 -> 1722 | F18: =Sumproduct(Expenses!$B$2:$B999,Month(Expenses!$A$2:$A999)=A18,year(Expenses!$A$2:$A999)=B18) -> 521.62 | G18: =Sumproduct('Staff Salaries'!$B$3:$B999,month('Staff Salaries'!$A$3:$A999)=$A18,year('Staff Salaries'!$A$3:$A999)=$B18) -> 0 | H18: =IFERROR(__xludf.DUMMYFUNCTION("sumproduct(importrange(""https://docs.google.com/spreadsheets/d/15CJ-h55pYD1KSEfDJoQc5rhrr0QtLCfpr6KnyxjMee4/edit#gid=71971023"",""Expired!E2:E""),Month(importrange(""https://docs.google.com/spreadsheets/d/15CJ-h55pYD1KSEfDJoQc5rhrr0QtLCfpr6KnyxjMee4/edit"&"#gid=71971023"",""Expired!a2:a""))=A18,year(importrange(""https://docs.google.com/spreadsheets/d/15CJ-h55pYD1KSEfDJoQc5rhrr0QtLCfpr6KnyxjMee4/edit#gid=71971023"",""Expired!a2:a""))=B18)"),0.0) -> 0 | I18: =sumproduct('Profit Distributions'!$B$2:$B999,Year('Profit Distributions'!$A$2:$A999)=B18,Month('Profit Distributions'!$A$2:$A999)=A18,'Profit Distributions'!$C$2:$C999<>"Savings") -> 2240 | J18: =sumproduct('Profit Distributions'!$B$2:$B999,Year('Profit Distributions'!$A$2:$A999)=B18,Month('Profit Distributions'!$A$2:$A999)=A18,'Profit Distributions'!$C$2:$C999="Savings") -> 200 | K18: =C18+D18-F18-G18-E18+H18 -> 1078.2968 | L18: =K18-J18 -> 878.29678 | M18: =L18+M17-I18 -> 1071.7491
A19: 12 | B19: 2023 | C19: =Sumproduct(Sales!$F$2:$F999,month(Sales!$A$2:$A999)=A19,year(Sales!$A$2:$A999)=B19) -> 2770.8581 | D19: =Sumproduct('Amazon Royalties'!$E$2:$E999,month('Amazon Royalties'!$B$2:$B999)=A19,year('Amazon Royalties'!$B$2:$B999)=B19) -> 57.873277 | E19: ='Teacher Salaries'!V20 -> 1976 | F19: =Sumproduct(Expenses!$B$2:$B999,Month(Expenses!$A$2:$A999)=A19,year(Expenses!$A$2:$A999)=B19) -> 209.99 | G19: =Sumproduct('Staff Salaries'!$B$3:$B999,month('Staff Salaries'!$A$3:$A999)=$A19,year('Staff Salaries'!$A$3:$A999)=$B19) -> 0 | H19: =IFERROR(__xludf.DUMMYFUNCTION("sumproduct(importrange(""https://docs.google.com/spreadsheets/d/15CJ-h55pYD1KSEfDJoQc5rhrr0QtLCfpr6KnyxjMee4/edit#gid=71971023"",""Expired!E2:E""),Month(importrange(""https://docs.google.com/spreadsheets/d/15CJ-h55pYD1KSEfDJoQc5rhrr0QtLCfpr6KnyxjMee4/edit"&"#gid=71971023"",""Expired!a2:a""))=A19,year(importrange(""https://docs.google.com/spreadsheets/d/15CJ-h55pYD1KSEfDJoQc5rhrr0QtLCfpr6KnyxjMee4/edit#gid=71971023"",""Expired!a2:a""))=B19)"),0.0) -> 0 | I19: =sumproduct('Profit Distributions'!$B$2:$B999,Year('Profit Distributions'!$A$2:$A999)=B19,Month('Profit Distributions'!$A$2:$A999)=A19,'Profit Distributions'!$C$2:$C999<>"Savings") -> 644 | J19: =sumproduct('Profit Distributions'!$B$2:$B999,Year('Profit Distributions'!$A$2:$A999)=B19,Month('Profit Distributions'!$A$2:$A999)=A19,'Profit Distributions'!$C$2:$C999="Savings") -> 0 | K19: =C19+D19-F19-G19-E19+H19 -> 642.74134 | L19: =K19-J19 -> 642.74134 | M19: =L19+M18-I19 -> 1070.4905
A20: 1 | B20: 2024 | C20: =Sumproduct(Sales!$F$2:$F999,month(Sales!$A$2:$A999)=A20,year(Sales!$A$2:$A999)=B20) -> 6476.5989 | D20: =Sumproduct('Amazon Royalties'!$E$2:$E999,month('Amazon Royalties'!$B$2:$B999)=A20,year('Amazon Royalties'!$B$2:$B999)=B20) -> 88.206357 | E20: ='Teacher Salaries'!V21 -> 2160 | F20: =Sumproduct(Expenses!$B$2:$B999,Month(Expenses!$A$2:$A999)=A20,year(Expenses!$A$2:$A999)=B20) -> 573.46 | G20: =Sumproduct('Staff Salaries'!$B$3:$B999,month('Staff Salaries'!$A$3:$A999)=$A20,year('Staff Salaries'!$A$3:$A999)=$B20) -> 150 | H20: =IFERROR(__xludf.DUMMYFUNCTION("sumproduct(importrange(""https://docs.google.com/spreadsheets/d/15CJ-h55pYD1KSEfDJoQc5rhrr0QtLCfpr6KnyxjMee4/edit#gid=71971023"",""Expired!E2:E""),Month(importrange(""https://docs.google.com/spreadsheets/d/15CJ-h55pYD1KSEfDJoQc5rhrr0QtLCfpr6KnyxjMee4/edit"&"#gid=71971023"",""Expired!a2:a""))=A20,year(importrange(""https://docs.google.com/spreadsheets/d/15CJ-h55pYD1KSEfDJoQc5rhrr0QtLCfpr6KnyxjMee4/edit#gid=71971023"",""Expired!a2:a""))=B20)"),0.0) -> 0 | I20: =sumproduct('Profit Distributions'!$B$2:$B999,Year('Profit Distributions'!$A$2:$A999)=B20,Month('Profit Distributions'!$A$2:$A999)=A20,'Profit Distributions'!$C$2:$C999<>"Savings") -> 550 | J20: =sumproduct('Profit Distributions'!$B$2:$B999,Year('Profit Distributions'!$A$2:$A999)=B20,Month('Profit Distributions'!$A$2:$A999)=A20,'Profit Distributions'!$C$2:$C999="Savings") -> 2700 | K20: =C20+D20-F20-G20-E20+H20 -> 3681.3452 | L20: =K20-J20 -> 981.34524 | M20: =L20+M19-I20 -> 1501.8357
A21: 2 | B21: 2024 | C21: =Sumproduct(Sales!$F$2:$F999,month(Sales!$A$2:$A999)=A21,year(Sales!$A$2:$A999)=B21) -> 3662.2423 | D21: =Sumproduct('Amazon Royalties'!$E$2:$E999,month('Amazon Royalties'!$B$2:$B999)=A21,year('Amazon Royalties'!$B$2:$B999)=B21) -> 165.03497 | E21: ='Teacher Salaries'!V22 -> 2096 | F21: =Sumproduct(Expenses!$B$2:$B999,Month(Expenses!$A$2:$A999)=A21,year(Expenses!$A$2:$A999)=B21) -> 223.76 | G21: =Sumproduct('Staff Salaries'!$B$3:$B999,month('Staff Salaries'!$A$3:$A999)=$A21,year('Staff Salaries'!$A$3:$A999)=$B21) -> 150 | H21: =IFERROR(__xludf.DUMMYFUNCTION("sumproduct(importrange(""https://docs.google.com/spreadsheets/d/15CJ-h55pYD1KSEfDJoQc5rhrr0QtLCfpr6KnyxjMee4/edit#gid=71971023"",""Expired!E2:E""),Month(importrange(""https://docs.google.com/spreadsheets/d/15CJ-h55pYD1KSEfDJoQc5rhrr0QtLCfpr6KnyxjMee4/edit"&"#gid=71971023"",""Expired!a2:a""))=A21,year(importrange(""https://docs.google.com/spreadsheets/d/15CJ-h55pYD1KSEfDJoQc5rhrr0QtLCfpr6KnyxjMee4/edit#gid=71971023"",""Expired!a2:a""))=B21)"),0.0) -> 0 | I21: =sumproduct('Profit Distributions'!$B$2:$B999,Year('Profit Distributions'!$A$2:$A999)=B21,Month('Profit Distributions'!$A$2:$A999)=A21,'Profit Distributions'!$C$2:$C999<>"Savings") -> 1000 | J21: =sumproduct('Profit Distributions'!$B$2:$B999,Year('Profit Distributions'!$A$2:$A999)=B21,Month('Profit Distributions'!$A$2:$A999)=A21,'Profit Distributions'!$C$2:$C999="Savings") -> 0 | K21: =C21+D21-F21-G21-E21+H21 -> 1357.5173 | L21: =K21-J21 -> 1357.5173 | M21: =L21+M20-I21 -> 1859.353
A22: 3 | B22: 2024 | C22: =Sumproduct(Sales!$F$2:$F999,month(Sales!$A$2:$A999)=A22,year(Sales!$A$2:$A999)=B22) -> 5508.3743 | D22: =Sumproduct('Amazon Royalties'!$E$2:$E999,month('Amazon Royalties'!$B$2:$B999)=A22,year('Amazon Royalties'!$B$2:$B999)=B22) -> 106.67002 | E22: ='Teacher Salaries'!V23 -> 2112 | F22: =Sumproduct(Expenses!$B$2:$B999,Month(Expenses!$A$2:$A999)=A22,year(Expenses!$A$2:$A999)=B22) -> 60.99 | G22: =Sumproduct('Staff Salaries'!$B$3:$B999,month('Staff Salaries'!$A$3:$A999)=$A22,year('Staff Salaries'!$A$3:$A999)=$B22) -> 150 | H22: =IFERROR(__xludf.DUMMYFUNCTION("sumproduct(importrange(""https://docs.google.com/spreadsheets/d/15CJ-h55pYD1KSEfDJoQc5rhrr0QtLCfpr6KnyxjMee4/edit#gid=71971023"",""Expired!E2:E""),Month(importrange(""https://docs.google.com/spreadsheets/d/15CJ-h55pYD1KSEfDJoQc5rhrr0QtLCfpr6KnyxjMee4/edit"&"#gid=71971023"",""Expired!a2:a""))=A22,year(importrange(""https://docs.google.com/spreadsheets/d/15CJ-h55pYD1KSEfDJoQc5rhrr0QtLCfpr6KnyxjMee4/edit#gid=71971023"",""Expired!a2:a""))=B22)"),0.0) -> 0 | I22: =sumproduct('Profit Distributions'!$B$2:$B999,Year('Profit Distributions'!$A$2:$A999)=B22,Month('Profit Distributions'!$A$2:$A999)=A22,'Profit Distributions'!$C$2:$C999<>"Savings") -> 808 | J22: =sumproduct('Profit Distributions'!$B$2:$B999,Year('Profit Distributions'!$A$2:$A999)=B22,Month('Profit Distributions'!$A$2:$A999)=A22,'Profit Distributions'!$C$2:$C999="Savings") -> 0 | K22: =C22+D22-F22-G22-E22+H22 -> 3292.0543 | L22: =K22-J22 -> 3292.0543 | M22: =L22+M21-I22 -> 4343.4073
A23: 4 | B23: 2024 | C23: =Sumproduct(Sales!$F$2:$F999,month(Sales!$A$2:$A999)=A23,year(Sales!$A$2:$A999)=B23) -> 4961.0471 | D23: =Sumproduct('Amazon Royalties'!$E$2:$E999,month('Amazon Royalties'!$B$2:$B999)=A23,year('Amazon Royalties'!$B$2:$B999)=B23) -> 85.422372 | E23: ='Teacher Salaries'!V24 -> 2136 | F23: =Sumproduct(Expenses!$B$2:$B999,Month(Expenses!$A$2:$A999)=A23,year(Expenses!$A$2:$A999)=B23) -> 169.99 | G23: =Sumproduct('Staff Salaries'!$B$3:$B999,month('Staff Salaries'!$A$3:$A999)=$A23,year('Staff Salaries'!$A$3:$A999)=$B23) -> 150 | H23: =IFERROR(__xludf.DUMMYFUNCTION("sumproduct(importrange(""https://docs.google.com/spreadsheets/d/15CJ-h55pYD1KSEfDJoQc5rhrr0QtLCfpr6KnyxjMee4/edit#gid=71971023"",""Expired!E2:E""),Month(importrange(""https://docs.google.com/spreadsheets/d/15CJ-h55pYD1KSEfDJoQc5rhrr0QtLCfpr6KnyxjMee4/edit"&"#gid=71971023"",""Expired!a2:a""))=A23,year(importrange(""https://docs.google.com/spreadsheets/d/15CJ-h55pYD1KSEfDJoQc5rhrr0QtLCfpr6KnyxjMee4/edit#gid=71971023"",""Expired!a2:a""))=B23)"),0.0) -> 0 | I23: =sumproduct('Profit Distributions'!$B$2:$B999,Year('Profit Distributions'!$A$2:$A999)=B23,Month('Profit Distributions'!$A$2:$A999)=A23,'Profit Distributions'!$C$2:$C999<>"Savings") -> 1000 | J23: =sumproduct('Profit Distributions'!$B$2:$B999,Year('Profit Distributions'!$A$2:$A999)=B23,Month('Profit Distributions'!$A$2:$A999)=A23,'Profit Distributions'!$C$2:$C999="Savings") -> 0 | K23: =C23+D23-F23-G23-E23+H23 -> 2590.4795 | L23: =K23-J23 -> 2590.4795 | M23: =L23+M22-I23 -> 5933.8868
A24: 5 | B24: 2024 | C24: =Sumproduct(Sales!$F$2:$F999,month(Sales!$A$2:$A999)=A24,year(Sales!$A$2:$A999)=B24) -> 4280.876 | D24: =Sumproduct('Amazon Royalties'!$E$2:$E999,month('Amazon Royalties'!$B$2:$B999)=A24,year('Amazon Royalties'!$B$2:$B999)=B24) -> 58.024046 | E24: ='Teacher Salaries'!V25 -> 2479 | F24: =Sumproduct(Expenses!$B$2:$B999,Month(Expenses!$A$2:$A999)=A24,year(Expenses!$A$2:$A999)=B24) -> 258.31 | G24: =Sumproduct('Staff Salaries'!$B$3:$B999,month('Staff Salaries'!$A$3:$A999)=$A24,year('Staff Salaries'!$A$3:$A999)=$B24) -> 150 | H24: =IFERROR(__xludf.DUMMYFUNCTION("sumproduct(importrange(""https://docs.google.com/spreadsheets/d/15CJ-h55pYD1KSEfDJoQc5rhrr0QtLCfpr6KnyxjMee4/edit#gid=71971023"",""Expired!E2:E""),Month(importrange(""https://docs.google.com/spreadsheets/d/15CJ-h55pYD1KSEfDJoQc5rhrr0QtLCfpr6KnyxjMee4/edit"&"#gid=71971023"",""Expired!a2:a""))=A24,year(importrange(""https://docs.google.com/spreadsheets/d/15CJ-h55pYD1KSEfDJoQc5rhrr0QtLCfpr6KnyxjMee4/edit#gid=71971023"",""Expired!a2:a""))=B24)"),0.0) -> 0 | I24: =sumproduct('Profit Distributions'!$B$2:$B999,Year('Profit Distributions'!$A$2:$A999)=B24,Month('Profit Distributions'!$A$2:$A999)=A24,'Profit Distributions'!$C$2:$C999<>"Savings") -> 6742 | J24: =sumproduct('Profit Distributions'!$B$2:$B999,Year('Profit Distributions'!$A$2:$A999)=B24,Month('Profit Distributions'!$A$2:$A999)=A24,'Profit Distributions'!$C$2:$C999="Savings") -> 640 | K24: =C24+D24-F24-G24-E24+H24 -> 1451.59 | L24: =K24-J24 -> 811.59003 | M24: =L24+M23-I24 -> 3.4768206
A25: 6 | B25: 2024 | C25: =Sumproduct(Sales!$F$2:$F999,month(Sales!$A$2:$A999)=A25,year(Sales!$A$2:$A999)=B25) -> 3360.93 | D25: =Sumproduct('Amazon Royalties'!$E$2:$E999,month('Amazon Royalties'!$B$2:$B999)=A25,year('Amazon Royalties'!$B$2:$B999)=B25) -> 131.37343 | E25: ='Teacher Salaries'!V26 -> 2487 | F25: =Sumproduct(Expenses!$B$2:$B999,Month(Expenses!$A$2:$A999)=A25,year(Expenses!$A$2:$A999)=B25) -> 216.99 | G25: =Sumproduct('Staff Salaries'!$B$3:$B999,month('Staff Salaries'!$A$3:$A999)=$A25,year('Staff Salaries'!$A$3:$A999)=$B25) -> 1592 | H25: =IFERROR(__xludf.DUMMYFUNCTION("sumproduct(importrange(""https://docs.google.com/spreadsheets/d/15CJ-h55pYD1KSEfDJoQc5rhrr0QtLCfpr6KnyxjMee4/edit#gid=71971023"",""Expired!E2:E""),Month(importrange(""https://docs.google.com/spreadsheets/d/15CJ-h55pYD1KSEfDJoQc5rhrr0QtLCfpr6KnyxjMee4/edit"&"#gid=71971023"",""Expired!a2:a""))=A25,year(importrange(""https://docs.google.com/spreadsheets/d/15CJ-h55pYD1KSEfDJoQc5rhrr0QtLCfpr6KnyxjMee4/edit#gid=71971023"",""Expired!a2:a""))=B25)"),0.0) -> 0 | I25: =sumproduct('Profit Distributions'!$B$2:$B999,Year('Profit Distributions'!$A$2:$A999)=B25,Month('Profit Distributions'!$A$2:$A999)=A25,'Profit Distributions'!$C$2:$C999<>"Savings") -> 0 | J25: =sumproduct('Profit Distributions'!$B$2:$B999,Year('Profit Distributions'!$A$2:$A999)=B25,Month('Profit Distributions'!$A$2:$A999)=A25,'Profit Distributions'!$C$2:$C999="Savings") -> 0 | K25: =C25+D25-F25-G25-E25+H25 -> -803.68655 | L25: =K25-J25 -> -803.68655 | M25: =L25+M24-I25 -> -800.20973
A26: 7 | B26: 2024 | C26: =Sumproduct(Sales!$F$2:$F999,month(Sales!$A$2:$A999)=A26,year(Sales!$A$2:$A999)=B26) -> 3307.98 | D26: =Sumproduct('Amazon Royalties'!$E$2:$E999,month('Amazon Royalties'!$B$2:$B999)=A26,year('Amazon Royalties'!$B$2:$B999)=B26) -> 68.396454 | E26: ='Teacher Salaries'!V27 -> 2255 | F26: =Sumproduct(Expenses!$B$2:$B999,Month(Expenses!$A$2:$A999)=A26,year(Expenses!$A$2:$A999)=B26) -> 326.99 | G26: =Sumproduct('Staff Salaries'!$B$3:$B999,month('Staff Salaries'!$A$3:$A999)=$A26,year('Staff Salaries'!$A$3:$A999)=$B26) -> 1622 | H26: =IFERROR(__xludf.DUMMYFUNCTION("sumproduct(importrange(""https://docs.google.com/spreadsheets/d/15CJ-h55pYD1KSEfDJoQc5rhrr0QtLCfpr6KnyxjMee4/edit#gid=71971023"",""Expired!E2:E""),Month(importrange(""https://docs.google.com/spreadsheets/d/15CJ-h55pYD1KSEfDJoQc5rhrr0QtLCfpr6KnyxjMee4/edit"&"#gid=71971023"",""Expired!a2:a""))=A26,year(importrange(""https://docs.google.com/spreadsheets/d/15CJ-h55pYD1KSEfDJoQc5rhrr0QtLCfpr6KnyxjMee4/edit#gid=71971023"",""Expired!a2:a""))=B26)"),0.0) -> 0 | I26: =sumproduct('Profit Distributions'!$B$2:$B999,Year('Profit Distributions'!$A$2:$A999)=B26,Month('Profit Distributions'!$A$2:$A999)=A26,'Profit Distributions'!$C$2:$C999<>"Savings") -> 0 | J26: =sumproduct('Profit Distributions'!$B$2:$B999,Year('Profit Distributions'!$A$2:$A999)=B26,Month('Profit Distributions'!$A$2:$A999)=A26,'Profit Distributions'!$C$2:$C999="Savings") -> 0 | K26: =C26+D26-F26-G26-E26+H26 -> -827.61351 | L26: =K26-J26 -> -827.61351 | M26: =L26+M25-I26 -> -1627.8232
A27: 8 | B27: 2024 | C27: =Sumproduct(Sales!$F$2:$F999,month(Sales!$A$2:$A999)=A27,year(Sales!$A$2:$A999)=B27) -> 5210.0269 | D27: =Sumproduct('Amazon Royalties'!$E$2:$E999,month('Amazon Royalties'!$B$2:$B999)=A27,year('Amazon Royalties'!$B$2:$B999)=B27) -> 72.54076 | E27: ='Teacher Salaries'!V28 -> 2413 | F27: =Sumproduct(Expenses!$B$2:$B999,Month(Expenses!$A$2:$A999)=A27,year(Expenses!$A$2:$A999)=B27) -> 134.1 | G27: =Sumproduct('Staff Salaries'!$B$3:$B999,month('Staff Salaries'!$A$3:$A999)=$A27,year('Staff Salaries'!$A$3:$A999)=$B27) -> 2736 | H27: =IFERROR(__xludf.DUMMYFUNCTION("sumproduct(importrange(""https://docs.google.com/spreadsheets/d/15CJ-h55pYD1KSEfDJoQc5rhrr0QtLCfpr6KnyxjMee4/edit#gid=71971023"",""Expired!E2:E""),Month(importrange(""https://docs.google.com/spreadsheets/d/15CJ-h55pYD1KSEfDJoQc5rhrr0QtLCfpr6KnyxjMee4/edit"&"#gid=71971023"",""Expired!a2:a""))=A27,year(importrange(""https://docs.google.com/spreadsheets/d/15CJ-h55pYD1KSEfDJoQc5rhrr0QtLCfpr6KnyxjMee4/edit#gid=71971023"",""Expired!a2:a""))=B27)"),0.0) -> 0 | I27: =sumproduct('Profit Distributions'!$B$2:$B999,Year('Profit Distributions'!$A$2:$A999)=B27,Month('Profit Distributions'!$A$2:$A999)=A27,'Profit Distributions'!$C$2:$C999<>"Savings") -> 0 | J27: =sumproduct('Profit Distributions'!$B$2:$B999,Year('Profit Distributions'!$A$2:$A999)=B27,Month('Profit Distributions'!$A$2:$A999)=A27,'Profit Distributions'!$C$2:$C999="Savings") -> 0 | K27: =C27+D27-F27-G27-E27+H27 -> -0.53229221 | L27: =K27-J27 -> -0.53229221 | M27: =L27+M26-I27 -> -1628.3555
A28: 9 | B28: 2024 | C28: =Sumproduct(Sales!$F$2:$F999,month(Sales!$A$2:$A999)=A28,year(Sales!$A$2:$A999)=B28) -> 4643.6149 | D28: =Sumproduct('Amazon Royalties'!$E$2:$E999,month('Amazon Royalties'!$B$2:$B999)=A28,year('Amazon Royalties'!$B$2:$B999)=B28) -> 72.45979 | E28: ='Teacher Salaries'!V29 -> 2618 | F28: =Sumproduct(Expenses!$B$2:$B999,Month(Expenses!$A$2:$A999)=A28,year(Expenses!$A$2:$A999)=B28) -> 243.99 | G28: =Sumproduct('Staff Salaries'!$B$3:$B999,month('Staff Salaries'!$A$3:$A999)=$A28,year('Staff Salaries'!$A$3:$A999)=$B28) -> 1865 | H28: =IFERROR(__xludf.DUMMYFUNCTION("sumproduct(importrange(""https://docs.google.com/spreadsheets/d/15CJ-h55pYD1KSEfDJoQc5rhrr0QtLCfpr6KnyxjMee4/edit#gid=71971023"",""Expired!E2:E""),Month(importrange(""https://docs.google.com/spreadsheets/d/15CJ-h55pYD1KSEfDJoQc5rhrr0QtLCfpr6KnyxjMee4/edit"&"#gid=71971023"",""Expired!a2:a""))=A28,year(importrange(""https://docs.google.com/spreadsheets/d/15CJ-h55pYD1KSEfDJoQc5rhrr0QtLCfpr6KnyxjMee4/edit#gid=71971023"",""Expired!a2:a""))=B28)"),0.0) -> 0 | I28: =sumproduct('Profit Distributions'!$B$2:$B999,Year('Profit Distributions'!$A$2:$A999)=B28,Month('Profit Distributions'!$A$2:$A999)=A28,'Profit Distributions'!$C$2:$C999<>"Savings") -> 0 | J28: =sumproduct('Profit Distributions'!$B$2:$B999,Year('Profit Distributions'!$A$2:$A999)=B28,Month('Profit Distributions'!$A$2:$A999)=A28,'Profit Distributions'!$C$2:$C999="Savings") -> 0 | K28: =C28+D28-F28-G28-E28+H28 -> -10.915288 | L28: =K28-J28 -> -10.915288 | M28: =L28+M27-I28 -> -1639.2708
A29: 10 | B29: 2024 | C29: =Sumproduct(Sales!$F$2:$F999,month(Sales!$A$2:$A999)=A29,year(Sales!$A$2:$A999)=B29) -> 5389.3621 | D29: =Sumproduct('Amazon Royalties'!$E$2:$E999,month('Amazon Royalties'!$B$2:$B999)=A29,year('Amazon Royalties'!$B$2:$B999)=B29) -> 61.672832 | E29: ='Teacher Salaries'!V30 -> 2903 | F29: =Sumproduct(Expenses!$B$2:$B999,Month(Expenses!$A$2:$A999)=A29,year(Expenses!$A$2:$A999)=B29) -> 216.15 | G29: =Sumproduct('Staff Salaries'!$B$3:$B999,month('Staff Salaries'!$A$3:$A999)=$A29,year('Staff Salaries'!$A$3:$A999)=$B29) -> 1600 | H29: =IFERROR(__xludf.DUMMYFUNCTION("sumproduct(importrange(""https://docs.google.com/spreadsheets/d/15CJ-h55pYD1KSEfDJoQc5rhrr0QtLCfpr6KnyxjMee4/edit#gid=71971023"",""Expired!E2:E""),Month(importrange(""https://docs.google.com/spreadsheets/d/15CJ-h55pYD1KSEfDJoQc5rhrr0QtLCfpr6KnyxjMee4/edit"&"#gid=71971023"",""Expired!a2:a""))=A29,year(importrange(""https://docs.google.com/spreadsheets/d/15CJ-h55pYD1KSEfDJoQc5rhrr0QtLCfpr6KnyxjMee4/edit#gid=71971023"",""Expired!a2:a""))=B29)"),0.0) -> 0 | I29: =sumproduct('Profit Distributions'!$B$2:$B999,Year('Profit Distributions'!$A$2:$A999)=B29,Month('Profit Distributions'!$A$2:$A999)=A29,'Profit Distributions'!$C$2:$C999<>"Savings") -> 0 | J29: =sumproduct('Profit Distributions'!$B$2:$B999,Year('Profit Distributions'!$A$2:$A999)=B29,Month('Profit Distributions'!$A$2:$A999)=A29,'Profit Distributions'!$C$2:$C999="Savings") -> 0 | K29: =C29+D29-F29-G29-E29+H29 -> 731.88498 | L29: =K29-J29 -> 731.88498 | M29: =L29+M28-I29 -> -907.38584
A30: 11 | B30: 2024 | C30: =Sumproduct(Sales!$F$2:$F999,month(Sales!$A$2:$A999)=A30,year(Sales!$A$2:$A999)=B30) -> 3662.09 | D30: =Sumproduct('Amazon Royalties'!$E$2:$E999,month('Amazon Royalties'!$B$2:$B999)=A30,year('Amazon Royalties'!$B$2:$B999)=B30) -> 86.125913 | E30: ='Teacher Salaries'!V31 -> 2991 | F30: =Sumproduct(Expenses!$B$2:$B999,Month(Expenses!$A$2:$A999)=A30,year(Expenses!$A$2:$A999)=B30) -> 230.8 | G30: =Sumproduct('Staff Salaries'!$B$3:$B999,month('Staff Salaries'!$A$3:$A999)=$A30,year('Staff Salaries'!$A$3:$A999)=$B30) -> 1600 | H30: =IFERROR(__xludf.DUMMYFUNCTION("sumproduct(importrange(""https://docs.google.com/spreadsheets/d/15CJ-h55pYD1KSEfDJoQc5rhrr0QtLCfpr6KnyxjMee4/edit#gid=71971023"",""Expired!E2:E""),Month(importrange(""https://docs.google.com/spreadsheets/d/15CJ-h55pYD1KSEfDJoQc5rhrr0QtLCfpr6KnyxjMee4/edit"&"#gid=71971023"",""Expired!a2:a""))=A30,year(importrange(""https://docs.google.com/spreadsheets/d/15CJ-h55pYD1KSEfDJoQc5rhrr0QtLCfpr6KnyxjMee4/edit#gid=71971023"",""Expired!a2:a""))=B30)"),0.0) -> 0 | I30: =sumproduct('Profit Distributions'!$B$2:$B999,Year('Profit Distributions'!$A$2:$A999)=B30,Month('Profit Distributions'!$A$2:$A999)=A30,'Profit Distributions'!$C$2:$C999<>"Savings") -> 0 | J30: =sumproduct('Profit Distributions'!$B$2:$B999,Year('Profit Distributions'!$A$2:$A999)=B30,Month('Profit Distributions'!$A$2:$A999)=A30,'Profit Distributions'!$C$2:$C999="Savings") -> 0 | K30: =C30+D30-F30-G30-E30+H30 -> -1073.5841 | L30: =K30-J30 -> -1073.5841 | M30: =L30+M29-I30 -> -1980.9699
A31: 12 | B31: 2024 | C31: =Sumproduct(Sales!$F$2:$F999,month(Sales!$A$2:$A999)=A31,year(Sales!$A$2:$A999)=B31) -> 4073.8 | D31: =Sumproduct('Amazon Royalties'!$E$2:$E999,month('Amazon Royalties'!$B$2:$B999)=A31,year('Amazon Royalties'!$B$2:$B999)=B31) -> 124.84247 | E31: ='Teacher Salaries'!V32 -> 3047 | F31: =Sumproduct(Expenses!$B$2:$B999,Month(Expenses!$A$2:$A999)=A31,year(Expenses!$A$2:$A999)=B31) -> 419.11 | G31: =Sumproduct('Staff Salaries'!$B$3:$B999,month('Staff Salaries'!$A$3:$A999)=$A31,year('Staff Salaries'!$A$3:$A999)=$B31) -> 1700 | H31: =IFERROR(__xludf.DUMMYFUNCTION("sumproduct(importrange(""https://docs.google.com/spreadsheets/d/15CJ-h55pYD1KSEfDJoQc5rhrr0QtLCfpr6KnyxjMee4/edit#gid=71971023"",""Expired!E2:E""),Month(importrange(""https://docs.google.com/spreadsheets/d/15CJ-h55pYD1KSEfDJoQc5rhrr0QtLCfpr6KnyxjMee4/edit"&"#gid=71971023"",""Expired!a2:a""))=A31,year(importrange(""https://docs.google.com/spreadsheets/d/15CJ-h55pYD1KSEfDJoQc5rhrr0QtLCfpr6KnyxjMee4/edit#gid=71971023"",""Expired!a2:a""))=B31)"),0.0) -> 0 | I31: =sumproduct('Profit Distributions'!$B$2:$B999,Year('Profit Distributions'!$A$2:$A999)=B31,Month('Profit Distributions'!$A$2:$A999)=A31,'Profit Distributions'!$C$2:$C999<>"Savings") -> 0 | J31: =sumproduct('Profit Distributions'!$B$2:$B999,Year('Profit Distributions'!$A$2:$A999)=B31,Month('Profit Distributions'!$A$2:$A999)=A31,'Profit Distributions'!$C$2:$C999="Savings") -> 0 | K31: =C31+D31-F31-G31-E31+H31 -> -967.46753 | L31: =K31-J31 -> -967.46753 | M31: =L31+M30-I31 -> -2948.4375
A32: 1 | B32: 2025 | C32: =Sumproduct(Sales!$F$2:$F999,month(Sales!$A$2:$A999)=A32,year(Sales!$A$2:$A999)=B32) -> 7034.14 | D32: =Sumproduct('Amazon Royalties'!$E$2:$E999,month('Amazon Royalties'!$B$2:$B999)=A32,year('Amazon Royalties'!$B$2:$B999)=B32) -> 102.67837 | E32: ='Teacher Salaries'!V33 -> 3157 | F32: =Sumproduct(Expenses!$B$2:$B999,Month(Expenses!$A$2:$A999)=A32,year(Expenses!$A$2:$A999)=B32) -> 502.03 | G32: =Sumproduct('Staff Salaries'!$B$3:$B999,month('Staff Salaries'!$A$3:$A999)=$A32,year('Staff Salaries'!$A$3:$A999)=$B32) -> 1700 | H32: =IFERROR(__xludf.DUMMYFUNCTION("sumproduct(importrange(""https://docs.google.com/spreadsheets/d/15CJ-h55pYD1KSEfDJoQc5rhrr0QtLCfpr6KnyxjMee4/edit#gid=71971023"",""Expired!E2:E""),Month(importrange(""https://docs.google.com/spreadsheets/d/15CJ-h55pYD1KSEfDJoQc5rhrr0QtLCfpr6KnyxjMee4/edit"&"#gid=71971023"",""Expired!a2:a""))=A32,year(importrange(""https://docs.google.com/spreadsheets/d/15CJ-h55pYD1KSEfDJoQc5rhrr0QtLCfpr6KnyxjMee4/edit#gid=71971023"",""Expired!a2:a""))=B32)"),0.0) -> 0 | I32: =sumproduct('Profit Distributions'!$B$2:$B999,Year('Profit Distributions'!$A$2:$A999)=B32,Month('Profit Distributions'!$A$2:$A999)=A32,'Profit Distributions'!$C$2:$C999<>"Savings") -> 0 | J32: =sumproduct('Profit Distributions'!$B$2:$B999,Year('Profit Distributions'!$A$2:$A999)=B32,Month('Profit Distributions'!$A$2:$A999)=A32,'Profit Distributions'!$C$2:$C999="Savings") -> 0 | K32: =C32+D32-F32-G32-E32+H32 -> 1777.7884 | L32: =K32-J32 -> 1777.7884 | M32: =L32+M31-I32 -> -1170.6491
A33: 2 | B33: 2025 | C33: =Sumproduct(Sales!$F$2:$F999,month(Sales!$A$2:$A999)=A33,year(Sales!$A$2:$A999)=B33) -> 3304.26 | D33: =Sumproduct('Amazon Royalties'!$E$2:$E999,month('Amazon Royalties'!$B$2:$B999)=A33,year('Amazon Royalties'!$B$2:$B999)=B33) -> 120.80777 | E33: ='Teacher Salaries'!V34 -> 3025 | F33: =Sumproduct(Expenses!$B$2:$B999,Month(Expenses!$A$2:$A999)=A33,year(Expenses!$A$2:$A999)=B33) -> 175.98 | G33: =Sumproduct('Staff Salaries'!$B$3:$B999,month('Staff Salaries'!$A$3:$A999)=$A33,year('Staff Salaries'!$A$3:$A999)=$B33) -> 1700 | H33: =IFERROR(__xludf.DUMMYFUNCTION("sumproduct(importrange(""https://docs.google.com/spreadsheets/d/15CJ-h55pYD1KSEfDJoQc5rhrr0QtLCfpr6KnyxjMee4/edit#gid=71971023"",""Expired!E2:E""),Month(importrange(""https://docs.google.com/spreadsheets/d/15CJ-h55pYD1KSEfDJoQc5rhrr0QtLCfpr6KnyxjMee4/edit"&"#gid=71971023"",""Expired!a2:a""))=A33,year(importrange(""https://docs.google.com/spreadsheets/d/15CJ-h55pYD1KSEfDJoQc5rhrr0QtLCfpr6KnyxjMee4/edit#gid=71971023"",""Expired!a2:a""))=B33)"),0.0) -> 0 | I33: =sumproduct('Profit Distributions'!$B$2:$B999,Year('Profit Distributions'!$A$2:$A999)=B33,Month('Profit Distributions'!$A$2:$A999)=A33,'Profit Distributions'!$C$2:$C999<>"Savings") -> 0 | J33: =sumproduct('Profit Distributions'!$B$2:$B999,Year('Profit Distributions'!$A$2:$A999)=B33,Month('Profit Distributions'!$A$2:$A999)=A33,'Profit Distributions'!$C$2:$C999="Savings") -> 0 | K33: =C33+D33-F33-G33-E33+H33 -> -1475.9122 | L33: =K33-J33 -> -1475.9122 | M33: =L33+M32-I33 -> -2646.5613
A34: 3 | B34: 2025 | C34: =Sumproduct(Sales!$F$2:$F999,month(Sales!$A$2:$A999)=A34,year(Sales!$A$2:$A999)=B34) -> 5362.18 | D34: =Sumproduct('Amazon Royalties'!$E$2:$E999,month('Amazon Royalties'!$B$2:$B999)=A34,year('Amazon Royalties'!$B$2:$B999)=B34) -> 71.816917 | E34: ='Teacher Salaries'!V35 -> 3277 | F34: =Sumproduct(Expenses!$B$2:$B999,Month(Expenses!$A$2:$A999)=A34,year(Expenses!$A$2:$A999)=B34) -> 135.98 | G34: =Sumproduct('Staff Salaries'!$B$3:$B999,month('Staff Salaries'!$A$3:$A999)=$A34,year('Staff Salaries'!$A$3:$A999)=$B34) -> 1700 | H34: =IFERROR(__xludf.DUMMYFUNCTION("sumproduct(importrange(""https://docs.google.com/spreadsheets/d/15CJ-h55pYD1KSEfDJoQc5rhrr0QtLCfpr6KnyxjMee4/edit#gid=71971023"",""Expired!E2:E""),Month(importrange(""https://docs.google.com/spreadsheets/d/15CJ-h55pYD1KSEfDJoQc5rhrr0QtLCfpr6KnyxjMee4/edit"&"#gid=71971023"",""Expired!a2:a""))=A34,year(importrange(""https://docs.google.com/spreadsheets/d/15CJ-h55pYD1KSEfDJoQc5rhrr0QtLCfpr6KnyxjMee4/edit#gid=71971023"",""Expired!a2:a""))=B34)"),0.0) -> 0 | I34: =sumproduct('Profit Distributions'!$B$2:$B999,Year('Profit Distributions'!$A$2:$A999)=B34,Month('Profit Distributions'!$A$2:$A999)=A34,'Profit Distributions'!$C$2:$C999<>"Savings") -> 0 | J34: =sumproduct('Profit Distributions'!$B$2:$B999,Year('Profit Distributions'!$A$2:$A999)=B34,Month('Profit Distributions'!$A$2:$A999)=A34,'Profit Distributions'!$C$2:$C999="Savings") -> 0 | K34: =C34+D34-F34-G34-E34+H34 -> 321.01692 | L34: =K34-J34 -> 321.01692 | M34: =L34+M33-I34 -> -2325.5444
A35: 4 | B35: 2025 | C35: =Sumproduct(Sales!$F$2:$F999,month(Sales!$A$2:$A999)=A35,year(Sales!$A$2:$A999)=B35) -> 4293.83 | D35: =Sumproduct('Amazon Royalties'!$E$2:$E999,month('Amazon Royalties'!$B$2:$B999)=A35,year('Amazon Royalties'!$B$2:$B999)=B35) -> 155.64116 | E35: ='Teacher Salaries'!V36 -> 3178 | F35: =Sumproduct(Expenses!$B$2:$B999,Month(Expenses!$A$2:$A999)=A35,year(Expenses!$A$2:$A999)=B35) -> 146.98 | G35: =Sumproduct('Staff Salaries'!$B$3:$B999,month('Staff Salaries'!$A$3:$A999)=$A35,year('Staff Salaries'!$A$3:$A999)=$B35) -> 1700 | H35: =IFERROR(__xludf.DUMMYFUNCTION("sumproduct(importrange(""https://docs.google.com/spreadsheets/d/15CJ-h55pYD1KSEfDJoQc5rhrr0QtLCfpr6KnyxjMee4/edit#gid=71971023"",""Expired!E2:E""),Month(importrange(""https://docs.google.com/spreadsheets/d/15CJ-h55pYD1KSEfDJoQc5rhrr0QtLCfpr6KnyxjMee4/edit"&"#gid=71971023"",""Expired!a2:a""))=A35,year(importrange(""https://docs.google.com/spreadsheets/d/15CJ-h55pYD1KSEfDJoQc5rhrr0QtLCfpr6KnyxjMee4/edit#gid=71971023"",""Expired!a2:a""))=B35)"),0.0) -> 0 | I35: =sumproduct('Profit Distributions'!$B$2:$B999,Year('Profit Distributions'!$A$2:$A999)=B35,Month('Profit Distributions'!$A$2:$A999)=A35,'Profit Distributions'!$C$2:$C999<>"Savings") -> 0 | J35: =sumproduct('Profit Distributions'!$B$2:$B999,Year('Profit Distributions'!$A$2:$A999)=B35,Month('Profit Distributions'!$A$2:$A999)=A35,'Profit Distributions'!$C$2:$C999="Savings") -> 0 | K35: =C35+D35-F35-G35-E35+H35 -> -575.50884 | L35: =K35-J35 -> -575.50884 | M35: =L35+M34-I35 -> -2901.0532
A36: 5 | B36: 2025 | C36: =Sumproduct(Sales!$F$2:$F999,month(Sales!$A$2:$A999)=A36,year(Sales!$A$2:$A999)=B36) -> 3945.89 | D36: =Sumproduct('Amazon Royalties'!$E$2:$E999,month('Amazon Royalties'!$B$2:$B999)=A36,year('Amazon Royalties'!$B$2:$B999)=B36) -> 65.541745 | E36: ='Teacher Salaries'!V37 -> 3211 | F36: =Sumproduct(Expenses!$B$2:$B999,Month(Expenses!$A$2:$A999)=A36,year(Expenses!$A$2:$A999)=B36) -> 313.6 | G36: =Sumproduct('Staff Salaries'!$B$3:$B999,month('Staff Salaries'!$A$3:$A999)=$A36,year('Staff Salaries'!$A$3:$A999)=$B36) -> 1700 | H36: =IFERROR(__xludf.DUMMYFUNCTION("sumproduct(importrange(""https://docs.google.com/spreadsheets/d/15CJ-h55pYD1KSEfDJoQc5rhrr0QtLCfpr6KnyxjMee4/edit#gid=71971023"",""Expired!E2:E""),Month(importrange(""https://docs.google.com/spreadsheets/d/15CJ-h55pYD1KSEfDJoQc5rhrr0QtLCfpr6KnyxjMee4/edit"&"#gid=71971023"",""Expired!a2:a""))=A36,year(importrange(""https://docs.google.com/spreadsheets/d/15CJ-h55pYD1KSEfDJoQc5rhrr0QtLCfpr6KnyxjMee4/edit#gid=71971023"",""Expired!a2:a""))=B36)"),0.0) -> 0 | I36: =sumproduct('Profit Distributions'!$B$2:$B999,Year('Profit Distributions'!$A$2:$A999)=B36,Month('Profit Distributions'!$A$2:$A999)=A36,'Profit Distributions'!$C$2:$C999<>"Savings") -> 0 | J36: =sumproduct('Profit Distributions'!$B$2:$B999,Year('Profit Distributions'!$A$2:$A999)=B36,Month('Profit Distributions'!$A$2:$A999)=A36,'Profit Distributions'!$C$2:$C999="Savings") -> -3000 | K36: =C36+D36-F36-G36-E36+H36 -> -1213.1683 | L36: =K36-J36 -> 1786.8317 | M36: =L36+M35-I36 -> -1114.2215
A37: 6 | B37: 2025 | C37: =Sumproduct(Sales!$F$2:$F999,month(Sales!$A$2:$A999)=A37,year(Sales!$A$2:$A999)=B37) -> 2738.89 | D37: =Sumproduct('Amazon Royalties'!$E$2:$E999,month('Amazon Royalties'!$B$2:$B999)=A37,year('Amazon Royalties'!$B$2:$B999)=B37) -> 48.84004 | E37: ='Teacher Salaries'!V38 -> 2818 | F37: =Sumproduct(Expenses!$B$2:$B999,Month(Expenses!$A$2:$A999)=A37,year(Expenses!$A$2:$A999)=B37) -> 202.18 | G37: =Sumproduct('Staff Salaries'!$B$3:$B999,month('Staff Salaries'!$A$3:$A999)=$A37,year('Staff Salaries'!$A$3:$A999)=$B37) -> 1700 | H37: =IFERROR(__xludf.DUMMYFUNCTION("sumproduct(importrange(""https://docs.google.com/spreadsheets/d/15CJ-h55pYD1KSEfDJoQc5rhrr0QtLCfpr6KnyxjMee4/edit#gid=71971023"",""Expired!E2:E""),Month(importrange(""https://docs.google.com/spreadsheets/d/15CJ-h55pYD1KSEfDJoQc5rhrr0QtLCfpr6KnyxjMee4/edit"&"#gid=71971023"",""Expired!a2:a""))=A37,year(importrange(""https://docs.google.com/spreadsheets/d/15CJ-h55pYD1KSEfDJoQc5rhrr0QtLCfpr6KnyxjMee4/edit#gid=71971023"",""Expired!a2:a""))=B37)"),0.0) -> 0 | I37: =sumproduct('Profit Distributions'!$B$2:$B999,Year('Profit Distributions'!$A$2:$A999)=B37,Month('Profit Distributions'!$A$2:$A999)=A37,'Profit Distributions'!$C$2:$C999<>"Savings") -> 0 | J37: =sumproduct('Profit Distributions'!$B$2:$B999,Year('Profit Distributions'!$A$2:$A999)=B37,Month('Profit Distributions'!$A$2:$A999)=A37,'Profit Distributions'!$C$2:$C999="Savings") -> 0 | K37: =C37+D37-F37-G37-E37+H37 -> -1932.45 | L37: =K37-J37 -> -1932.45 | M37: =L37+M36-I37 -> -3046.6715
A38: 7 | B38: 2025 | C38: =Sumproduct(Sales!$F$2:$F999,month(Sales!$A$2:$A999)=A38,year(Sales!$A$2:$A999)=B38) -> 4263.42 | D38: =Sumproduct('Amazon Royalties'!$E$2:$E999,month('Amazon Royalties'!$B$2:$B999)=A38,year('Amazon Royalties'!$B$2:$B999)=B38) -> 91.24263 | E38: ='Teacher Salaries'!V39 -> 2906 | F38: =Sumproduct(Expenses!$B$2:$B999,Month(Expenses!$A$2:$A999)=A38,year(Expenses!$A$2:$A999)=B38) -> 286.18 | G38: =Sumproduct('Staff Salaries'!$B$3:$B999,month('Staff Salaries'!$A$3:$A999)=$A38,year('Staff Salaries'!$A$3:$A999)=$B38) -> 1700 | H38: =IFERROR(__xludf.DUMMYFUNCTION("sumproduct(importrange(""https://docs.google.com/spreadsheets/d/15CJ-h55pYD1KSEfDJoQc5rhrr0QtLCfpr6KnyxjMee4/edit#gid=71971023"",""Expired!E2:E""),Month(importrange(""https://docs.google.com/spreadsheets/d/15CJ-h55pYD1KSEfDJoQc5rhrr0QtLCfpr6KnyxjMee4/edit"&"#gid=71971023"",""Expired!a2:a""))=A38,year(importrange(""https://docs.google.com/spreadsheets/d/15CJ-h55pYD1KSEfDJoQc5rhrr0QtLCfpr6KnyxjMee4/edit#gid=71971023"",""Expired!a2:a""))=B38)"),0.0) -> 0 | I38: =sumproduct('Profit Distributions'!$B$2:$B999,Year('Profit Distributions'!$A$2:$A999)=B38,Month('Profit Distributions'!$A$2:$A999)=A38,'Profit Distributions'!$C$2:$C999<>"Savings") -> 0 | J38: =sumproduct('Profit Distributions'!$B$2:$B999,Year('Profit Distributions'!$A$2:$A999)=B38,Month('Profit Distributions'!$A$2:$A999)=A38,'Profit Distributions'!$C$2:$C999="Savings") -> 0 | K38: =C38+D38-F38-G38-E38+H38 -> -537.51737 | L38: =K38-J38 -> -537.51737 | M38: =L38+M37-I38 -> -3584.1888
A39: 8 | B39: 2025 | C39: =Sumproduct(Sales!$F$2:$F999,month(Sales!$A$2:$A999)=A39,year(Sales!$A$2:$A999)=B39) -> 2948.53 | D39: =Sumproduct('Amazon Royalties'!$E$2:$E999,month('Amazon Royalties'!$B$2:$B999)=A39,year('Amazon Royalties'!$B$2:$B999)=B39) -> 71.646288 | E39: ='Teacher Salaries'!V40 -> 2895 | F39: =Sumproduct(Expenses!$B$2:$B999,Month(Expenses!$A$2:$A999)=A39,year(Expenses!$A$2:$A999)=B39) -> 302.64 | G39: =Sumproduct('Staff Salaries'!$B$3:$B999,month('Staff Salaries'!$A$3:$A999)=$A39,year('Staff Salaries'!$A$3:$A999)=$B39) -> 1700 | H39: =IFERROR(__xludf.DUMMYFUNCTION("sumproduct(importrange(""https://docs.google.com/spreadsheets/d/15CJ-h55pYD1KSEfDJoQc5rhrr0QtLCfpr6KnyxjMee4/edit#gid=71971023"",""Expired!E2:E""),Month(importrange(""https://docs.google.com/spreadsheets/d/15CJ-h55pYD1KSEfDJoQc5rhrr0QtLCfpr6KnyxjMee4/edit"&"#gid=71971023"",""Expired!a2:a""))=A39,year(importrange(""https://docs.google.com/spreadsheets/d/15CJ-h55pYD1KSEfDJoQc5rhrr0QtLCfpr6KnyxjMee4/edit#gid=71971023"",""Expired!a2:a""))=B39)"),0.0) -> 0 | I39: =sumproduct('Profit Distributions'!$B$2:$B999,Year('Profit Distributions'!$A$2:$A999)=B39,Month('Profit Distributions'!$A$2:$A999)=A39,'Profit Distributions'!$C$2:$C999<>"Savings") -> 0 | J39: =sumproduct('Profit Distributions'!$B$2:$B999,Year('Profit Distributions'!$A$2:$A999)=B39,Month('Profit Distributions'!$A$2:$A999)=A39,'Profit Distributions'!$C$2:$C999="Savings") -> -2140 | K39: =C39+D39-F39-G39-E39+H39 -> -1877.4637 | L39: =K39-J39 -> 262.53629 | M39: =L39+M38-I39 -> -3321.6525
