Workbook

Sheet Sheet1
A1: English | B1: English Proper | C1: Latin | D1: Latin fixed | E1: Arabic | F1: Video | G1: title | H1: order | I1: Chapter | J1: subchapter
A2: Time | B2: =UPPER(LEFT(A2,1))&LOWER(RIGHT(A2,LEN(A2)-1)) -> Time | C2: waeit | D2: wa'et | E2: وَقت | F2: 37 | G2: clock | H2: 1 | I2: 1 | J2: 1
A3: Timing | B3: =UPPER(LEFT(A3,1))&LOWER(RIGHT(A3,LEN(A3)-1)) -> Timing | C3: touw'it | D3: touw'eet | E3: توقيت | F3: 37 | G3: clock | H3: 1 | I3: 1 | J3: 1
A4: Hour | B4: =UPPER(LEFT(A4,1))&LOWER(RIGHT(A4,LEN(A4)-1)) -> Hour | C4: se3a | D4: sei3a | E4: ساعَة | F4: 37 | G4: clock | H4: 1 | I4: 1 | J4: 1 | L4: 37 | M4: clock
A5: 2 hours | B5: =UPPER(LEFT(A5,1))&LOWER(RIGHT(A5,LEN(A5)-1)) -> 2 hours | C5: se3tein | D5: se3tein | E5: ساعتين | F5: 37 | G5: clock | H5: 1 | I5: 1 | J5: 1 | L5: 30 | M5: Interrogative
A6: Hours | B6: =UPPER(LEFT(A6,1))&LOWER(RIGHT(A6,LEN(A6)-1)) -> Hours | C6: se3at | D6: se3at | E6: ساعات | F6: 37 | G6: clock | H6: 1 | I6: 1 | J6: 1 | L6: 39 | M6: To love
A7: Minute | B7: =UPPER(LEFT(A7,1))&LOWER(RIGHT(A7,LEN(A7)-1)) -> Minute | C7: d'i'a | D7: d'i'a | E7: دقيقَة | F7: 37 | G7: clock | H7: 1 | I7: 1 | J7: 1 | L7: 38 | M7: To Travel
A8: 2 minutes | B8: =UPPER(LEFT(A8,1))&LOWER(RIGHT(A8,LEN(A8)-1)) -> 2 minutes | C8: d'i'tein | D8: d'i'tein | E8: دقيقتين | F8: 37 | G8: clock | H8: 1 | I8: 1 | J8: 1 | L8: 25 | M8: Inside the house
A9: Minutes | B9: =UPPER(LEFT(A9,1))&LOWER(RIGHT(A9,LEN(A9)-1)) -> Minutes | C9: da'eyi' | D9: da'eyi' | E9: دَقايق | F9: 37 | G9: clock | H9: 1 | I9: 1 | J9: 1 | L9: 27 | M9: Ordering food
A10: Second | B10: =UPPER(LEFT(A10,1))&LOWER(RIGHT(A10,LEN(A10)-1)) -> Second | C10: seinyeh | D10: seinyeh | E10: ثانية | F10: 37 | G10: clock | H10: 1 | I10: 1 | J10: 1 | L10: 32 | M10: Winter
A11: 2 seconds | B11: =UPPER(LEFT(A11,1))&LOWER(RIGHT(A11,LEN(A11)-1)) -> 2 seconds | C11: senitein | D11: senitein | E11: ثانتين | F11: 37 | G11: clock | H11: 1 | I11: 1 | J11: 1 | L11: 29 | M11: Studying
A12: Seconds | B12: =UPPER(LEFT(A12,1))&LOWER(RIGHT(A12,LEN(A12)-1)) -> Seconds | C12: saweineih | D12: saweineh | E12: ثواني | F12: 37 | G12: clock | H12: 1 | I12: 1 | J12: 1 | L12: 31 | M12: Jobs
A13: A.M | B13: =UPPER(LEFT(A13,1))&LOWER(RIGHT(A13,LEN(A13)-1)) -> A.m | C13: abeil el doheir | D13: abel el doher | E13: قَبل الضُهر | F13: 37 | G13: clock | H13: 1 | I13: 1 | J13: 1 | L13: 26 | M13: Body parts
A14: P.M | B14: =UPPER(LEFT(A14,1))&LOWER(RIGHT(A14,LEN(A14)-1)) -> P.m | C14: ba3eid el doheir | D14: ba3ed el doher | E14: بَعد الضُهر | F14: 37 | G14: clock | H14: 1 | I14: 1 | J14: 1 | L14: 33 | M14: Doctor
A15: It's late | B15: =UPPER(LEFT(A15,1))&LOWER(RIGHT(A15,LEN(A15)-1)) -> It's late | C15: m'akhar | D15: m'akhar | E15: مأخَّر | F15: 37 | G15: clock | H15: 1 | I15: 1 | J15: 1 | L15: 35 | M15: politics 1
... A19: 5 past 6 | B19: =UPPER(LEFT(A19,1))&LOWER(RIGHT(A19,LEN(A19)-1)) -> 5 past 6 | C19: seitteih w khamseih | D19: setteh w khamseh | E19: ستّة و خَمسة | F19: 37 | G19: clock | H19: 2 | I19: 1 | J19: 1 | L19: 28 | M19: World cup
A20: 5 to 6 | B20: =UPPER(LEFT(A20,1))&LOWER(RIGHT(A20,LEN(A20)-1)) -> 5 to 6 | C20: seitteih 'ella khamseih | D20: setteh 'ella khamseh | E20: ستّة إلاّ خَمسة | F20: 37 | G20: clock | H20: 2 | I20: 1 | J20: 1
A21: 0.48958333 | B21: 0.48958333 | C21: tna3ch 'ella rebe3 | D21: tna3sh 'ella rebe3 | E21: تنعش و ربع | F21: 37 | G21: clock | H21: 2 | I21: 1 | J21: 1
A22: 0.10416667 | B22: 0.10416667 | C22: tnein(tentein) w noss | D22: tnein(tentein) w noss | E22: تنين (تنتين) و نُصّ | F22: 37 | G22: clock | H22: 2 | I22: 1 | J22: 1
A23: 0.14236111 | B23: 0.14236111 | C23: tleiteih w noss 'ella khamseih | D23: tleiteh w noss 'ella khamseh | E23: تلاتي و نُصّ إلاّ خَمسة | F23: 37 | G23: clock | H23: 2 | I23: 1 | J23: 1
A24: 0.14930556 | B24: 0.14930556 | C24: tleiteih w noss w khamseih | D24: tleiteh w noss w khamseh | E24: تلاتي و نُصّ و خَمسة | F24: 37 | G24: clock | H24: 2 | I24: 1 | J24: 1
A25: 0.13541667 | B25: 0.13541667 | C25: tleiteih w rebe3 | D25: tleiteh w rebe3 | E25: تلاتي و ربع | F25: 37 | G25: clock | H25: 2 | I25: 1 | J25: 1
A26: 0.13888889 | B26: 0.13888889 | C26: tleiteih w teileit | D26: tleiteh w telet | E26: تلاتي و تلت | F26: 37 | G26: clock | H26: 2 | I26: 1 | J26: 1
A27: 0.15277778 | B27: 0.15277778 | C27: arb3a 'ella teileit | D27: arb3a 'ella telet | E27: أربعَة إلاّ تلت | F27: 37 | G27: clock | H27: 2 | I27: 1 | J27: 1
A28: I'll be there in an hour or two | B28: =UPPER(LEFT(A28,1))&LOWER(RIGHT(A28,LEN(A28)-1)) -> I'll be there in an hour or two | C28: rah ousal ba3eid se3a aw se3tein | D28: raH ousal ba3ed sei3a aw se3tein | E28: رَ أوصَل بَعد ساعَة أو ساعتَين | F28: 37 | G28: clock | H28: 3 | I28: 1 | J28: 1
A29: I waited for yu for half an hour | B29: =UPPER(LEFT(A29,1))&LOWER(RIGHT(A29,LEN(A29)-1)) -> I waited for yu for half an hour | C29: natartak/ natartik noss se3a | D29: natartak/ natartik noss sei3a | E29: نَطَرتَك/ نَطَرتِك نُصّ ساعَة | F29: 37 | G29: clock | H29: 3 | I29: 1 | J29: 1
A30: My sister is arriving in 3 hours | B30: =UPPER(LEFT(A30,1))&LOWER(RIGHT(A30,LEN(A30)-1)) -> My sister is arriving in 3 hours | C30: ekhteih wasleh (rah tousal) ba3eid tleit se3at | D30: ekhteh wasleh (raH tousal) ba3ed tleit se3at | E30: إختي واصلي (رَح توصَل) بَعد تلات ساعات | F30: 37 | G30: clock | H30: 3 | I30: 1 | J30: 1
A31: 1 minute and i will be with you | B31: =UPPER(LEFT(A31,1))&LOWER(RIGHT(A31,LEN(A31)-1)) -> 1 minute and i will be with you | C31: d'i'a w bkoun ma3ak/ ma3ik | D31: d'i'a w bkoun ma3ak/ ma3ik | E31: دقيقَة و بكون مَعَك | F31: 37 | G31: clock | H31: 3 | I31: 1 | J31: 1
A32: What time is it in Canada time? | B32: =UPPER(LEFT(A32,1))&LOWER(RIGHT(A32,LEN(A32)-1)) -> What time is it in canada time? | C32: addeih el se3a bi touw'it canada? | D32: addeh el sei3a bi touw'eet canada? | E32: ادّي الساعَة بتوقيت كَنَدا؟ | F32: 37 | G32: clock | H32: 3 | I32: 1 | J32: 1
A33: I have a meeting tomorrow at 5 pm | B33: =UPPER(LEFT(A33,1))&LOWER(RIGHT(A33,LEN(A33)-1)) -> I have a meeting tomorrow at 5 pm | C33: 3andeih ejtimei3/ maw3ad boukra 3al se3a khamseih ba3eid el doheir | D33: 3andeh ejtimei3/ maw3ad boukra 3al sei3a khamseh ba3ed el doher | E33: عَندي إجتماع/ مَوعَد بُكرا على ساعَة خَمسة بَعد الضٌهر | F33: 37 | G33: clock | H33: 3 | I33: 1 | J33: 1
A34: Why | B34: =UPPER(LEFT(A34,1))&LOWER(RIGHT(A34,LEN(A34)-1)) -> Why | C34: leh/lech | D34: leh/lesh? | E34: ليه/ ليش | F34: 30 | G34: Interrogative | H34: 1 | I34: 1 | J34: 2
A35: When | B35: =UPPER(LEFT(A35,1))&LOWER(RIGHT(A35,LEN(A35)-1)) -> When | C35: eimtan | D35: eimtan? | E35: أمتَن | F35: 30 | G35: Interrogative | H35: 1 | I35: 1 | J35: 2
A36: Who | B36: =UPPER(LEFT(A36,1))&LOWER(RIGHT(A36,LEN(A36)-1)) -> Who | C36: min | D36: meen? | E36: مين | F36: 30 | G36: Interrogative | H36: 1 | I36: 1 | J36: 2
A37: How | B37: =UPPER(LEFT(A37,1))&LOWER(RIGHT(A37,LEN(A37)-1)) -> How | C37: kif | D37: keef? | E37: كيف | F37: 30 | G37: Interrogative | H37: 1 | I37: 1 | J37: 2
A38: What | B38: =UPPER(LEFT(A38,1))&LOWER(RIGHT(A38,LEN(A38)-1)) -> What | C38: chou | D38: shou? | E38: شو | F38: 30 | G38: Interrogative | H38: 1 | I38: 1 | J38: 2
A39: Where | B39: =UPPER(LEFT(A39,1))&LOWER(RIGHT(A39,LEN(A39)-1)) -> Where | C39: wein | D39: wein? | E39: وَين | F39: 30 | G39: Interrogative | H39: 1 | I39: 1 | J39: 2
... A60: I love | B60: =UPPER(LEFT(A60,1))&LOWER(RIGHT(A60,LEN(A60)-1)) -> I love | C60: ana bHeb | D60: ana bHebb | E60: أنا بحبّ | F60: 39 | G60: To Love | H60: 1 | I60: 2 | J60: 1
A61: you love | B61: =UPPER(LEFT(A61,1))&LOWER(RIGHT(A61,LEN(A61)-1)) -> You love | C61: enta betHeb/enteh betHebbeh | D61: enta betHebb/enteh betHebbeh | E61: إنتَ بتحبّ/ إنتِ بتحبّي | F61: 39 | G61: To Love | H61: 1 | I61: 2 | J61: 1 | L61: 37 | M61: clock
A62: he loves | B62: =UPPER(LEFT(A62,1))&LOWER(RIGHT(A62,LEN(A62)-1)) -> He loves | C62: howeh biHeb | D62: howeh biHebb | E62: هوّ بِحبّ | F62: 39 | G62: To Love | H62: 1 | I62: 2 | J62: 1 | L62: 30 | M62: Interrogative
A63: she loves | B63: =UPPER(LEFT(A63,1))&LOWER(RIGHT(A63,LEN(A63)-1)) -> She loves | C63: hiyyeh betHeb | D63: hiyyeh betHebb | E63: هِيّ بتحبّ | F63: 39 | G63: To Love | H63: 1 | I63: 2 | J63: 1 | L63: 39 | M63: To love
...

Sheet chapters
A1: 37 | B1: clock | C1: 1 | D1: 1 | E1: Basic | F1: =SUM(COUNTIF(Sheet1!F:F,34),COUNTIF(Sheet1!F:F,37)) -> 51 | G1: 1
A2: 30 | B2: Interrogative | C2: 1 | D2: 2 | E2: Conjugation | F2: =SUM(COUNTIF(Sheet1!F:F,38),COUNTIF(Sheet1!F:F,39)) -> 71 | G2: 2
A3: 39 | B3: To love | C3: 2 | D3: 1 | E3: At Home | F3: =SUM(COUNTIF(Sheet1!F:F,27),COUNTIF(Sheet1!F:F,25),COUNTIF(Sheet1!F:F,32)) -> 91 | G3: 3
A4: 38 | B4: To Travel | C4: 2 | D4: 2 | E4: Work/studying | F4: =SUM(COUNTIF(Sheet1!F:F,31),COUNTIF(Sheet1!F:F,29)) -> 39 | G4: 4
A5: 25 | B5: Inside the house | C5: 3 | D5: 1 | E5: Doctor | F5: =SUM(COUNTIF(Sheet1!F:F,33),COUNTIF(Sheet1!F:F,26)) -> 63 | G5: 5
A6: 27 | B6: Ordering food | C6: 3 | D6: 2 | E6: Politics | F6: =SUM(COUNTIF(Sheet1!F:F,35),COUNTIF(Sheet1!F:F,36)) -> 36 | G6: 6
A7: 32 | B7: Winter | C7: 3 | D7: 3 | E7: Formalities | F7: =SUM(COUNTIF(Sheet1!F:F,34),COUNTIF(Sheet1!F:F,40)) -> 55 | G7: 7
A8: 29 | B8: Studying | C8: 4 | D8: 1 | E8: World Cup | F8: =SUM(COUNTIF(Sheet1!F:F,28)) -> 19 | G8: 8
A9: 31 | B9: Jobs | C9: 4 | D9: 2
A10: 26 | B10: Body parts | C10: 5 | D10: 1
A11: 33 | B11: Doctor | C11: 5 | D11: 2
A12: 35 | B12: politics 1 | C12: 6 | D12: 1
A13: 36 | B13: politics 2 | C13: 6 | D13: 2
A14: 34 | B14: At the Door | C14: 7 | D14: 1
A15: 40 | B15: Please | C15: 7 | D15: 2
A16: 28 | B16: World cup | C16: 8 | D16: 1

Sheet Tables
A2: =IF(MOD(ROW()-2,2)=0, INDIRECT("Sheet1!A" &4+((ROW()-2)/2)-2), "") -> Time | B2: =IF(MOD(ROW()-2,2)=0, INDIRECT("Sheet1!D" &4+((ROW()-2)/2)-2), "") -> wa'et
B3: =IF(MOD(ROW()-3,2)=0, INDIRECT("Sheet1!E" &4+((ROW()-3)/2)-2), "") -> وَقت
A4: =IF(MOD(ROW()-2,2)=0, INDIRECT("Sheet1!A" &4+((ROW()-2)/2)-2), "") -> Timing | B4: =IF(MOD(ROW()-2,2)=0, INDIRECT("Sheet1!D" &4+((ROW()-2)/2)-2), "") -> touw'eet
B5: =IF(MOD(ROW()-3,2)=0, INDIRECT("Sheet1!E" &4+((ROW()-3)/2)-2), "") -> توقيت
A6: =IF(MOD(ROW()-2,2)=0, INDIRECT("Sheet1!A" &4+((ROW()-2)/2)-2), "") -> Hour | B6: =IF(MOD(ROW()-2,2)=0, INDIRECT("Sheet1!D" &4+((ROW()-2)/2)-2), "") -> sei3a
B7: =IF(MOD(ROW()-3,2)=0, INDIRECT("Sheet1!E" &4+((ROW()-3)/2)-2), "") -> ساعَة
A8: =IF(MOD(ROW()-2,2)=0, INDIRECT("Sheet1!A" &4+((ROW()-2)/2)-2), "") -> 2 hours | B8: =IF(MOD(ROW()-2,2)=0, INDIRECT("Sheet1!D" &4+((ROW()-2)/2)-2), "") -> se3tein
B9: =IF(MOD(ROW()-3,2)=0, INDIRECT("Sheet1!E" &4+((ROW()-3)/2)-2), "") -> ساعتين
A10: =IF(MOD(ROW()-2,2)=0, INDIRECT("Sheet1!A" &4+((ROW()-2)/2)-2), "") -> Hours | B10: =IF(MOD(ROW()-2,2)=0, INDIRECT("Sheet1!D" &4+((ROW()-2)/2)-2), "") -> se3at
B11: =IF(MOD(ROW()-3,2)=0, INDIRECT("Sheet1!E" &4+((ROW()-3)/2)-2), "") -> ساعات
A12: =IF(MOD(ROW()-2,2)=0, INDIRECT("Sheet1!A" &4+((ROW()-2)/2)-2), "") -> Minute | B12: =IF(MOD(ROW()-2,2)=0, INDIRECT("Sheet1!D" &4+((ROW()-2)/2)-2), "") -> d'i'a
B13: =IF(MOD(ROW()-3,2)=0, INDIRECT("Sheet1!E" &4+((ROW()-3)/2)-2), "") -> دقيقَة
A14: =IF(MOD(ROW()-2,2)=0, INDIRECT("Sheet1!A" &4+((ROW()-2)/2)-2), "") -> 2 minutes | B14: =IF(MOD(ROW()-2,2)=0, INDIRECT("Sheet1!D" &4+((ROW()-2)/2)-2), "") -> d'i'tein
B15: =IF(MOD(ROW()-3,2)=0, INDIRECT("Sheet1!E" &4+((ROW()-3)/2)-2), "") -> دقيقتين
A16: =IF(MOD(ROW()-2,2)=0, INDIRECT("Sheet1!A" &4+((ROW()-2)/2)-2), "") -> Minutes | B16: =IF(MOD(ROW()-2,2)=0, INDIRECT("Sheet1!D" &4+((ROW()-2)/2)-2), "") -> da'eyi'
B17: =IF(MOD(ROW()-3,2)=0, INDIRECT("Sheet1!E" &4+((ROW()-3)/2)-2), "") -> دَقايق
A18: =IF(MOD(ROW()-2,2)=0, INDIRECT("Sheet1!A" &4+((ROW()-2)/2)-2), "") -> Second | B18: =IF(MOD(ROW()-2,2)=0, INDIRECT("Sheet1!D" &4+((ROW()-2)/2)-2), "") -> seinyeh
B19: =IF(MOD(ROW()-3,2)=0, INDIRECT("Sheet1!E" &4+((ROW()-3)/2)-2), "") -> ثانية
A20: =IF(MOD(ROW()-2,2)=0, INDIRECT("Sheet1!A" &4+((ROW()-2)/2)-2), "") -> 2 seconds | B20: =IF(MOD(ROW()-2,2)=0, INDIRECT("Sheet1!D" &4+((ROW()-2)/2)-2), "") -> senitein
B21: =IF(MOD(ROW()-3,2)=0, INDIRECT("Sheet1!E" &4+((ROW()-3)/2)-2), "") -> ثانتين
A22: =IF(MOD(ROW()-2,2)=0, INDIRECT("Sheet1!A" &4+((ROW()-2)/2)-2), "") -> Seconds | B22: =IF(MOD(ROW()-2,2)=0, INDIRECT("Sheet1!D" &4+((ROW()-2)/2)-2), "") -> saweineh
B23: =IF(MOD(ROW()-3,2)=0, INDIRECT("Sheet1!E" &4+((ROW()-3)/2)-2), "") -> ثواني
A24: =IF(MOD(ROW()-2,2)=0, INDIRECT("Sheet1!A" &4+((ROW()-2)/2)-2), "") -> A.M | B24: =IF(MOD(ROW()-2,2)=0, INDIRECT("Sheet1!D" &4+((ROW()-2)/2)-2), "") -> abel el doher
B25: =IF(MOD(ROW()-3,2)=0, INDIRECT("Sheet1!E" &4+((ROW()-3)/2)-2), "") -> قَبل الضُهر
A26: =IF(MOD(ROW()-2,2)=0, INDIRECT("Sheet1!A" &4+((ROW()-2)/2)-2), "") -> P.M | B26: =IF(MOD(ROW()-2,2)=0, INDIRECT("Sheet1!D" &4+((ROW()-2)/2)-2), "") -> ba3ed el doher
B27: =IF(MOD(ROW()-3,2)=0, INDIRECT("Sheet1!E" &4+((ROW()-3)/2)-2), "") -> بَعد الضُهر
A28: =IF(MOD(ROW()-2,2)=0, INDIRECT("Sheet1!A" &4+((ROW()-2)/2)-2), "") -> It's late | B28: =IF(MOD(ROW()-2,2)=0, INDIRECT("Sheet1!D" &4+((ROW()-2)/2)-2), "") -> m'akhar
B29: =IF(MOD(ROW()-3,2)=0, INDIRECT("Sheet1!E" &4+((ROW()-3)/2)-2), "") -> مأخَّر
A30: =IF(MOD(ROW()-2,2)=0, INDIRECT("Sheet1!A" &4+((ROW()-2)/2)-2), "") -> It's early | B30: =IF(MOD(ROW()-2,2)=0, INDIRECT("Sheet1!D" &4+((ROW()-2)/2)-2), "") -> bakkeer
B31: =IF(MOD(ROW()-3,2)=0, INDIRECT("Sheet1!E" &4+((ROW()-3)/2)-2), "") -> بكّير
A32: =IF(MOD(ROW()-2,2)=0, INDIRECT("Sheet1!A" &4+((ROW()-2)/2)-2), "") -> What time is it? | B32: =IF(MOD(ROW()-2,2)=0, INDIRECT("Sheet1!D" &4+((ROW()-2)/2)-2), "") -> addeh el sei3a?
B33: =IF(MOD(ROW()-3,2)=0, INDIRECT("Sheet1!E" &4+((ROW()-3)/2)-2), "") -> أدّي الساعَة؟
A34: =IF(MOD(ROW()-2,2)=0, INDIRECT("Sheet1!A" &4+((ROW()-2)/2)-2), "") -> 10 to 1 | B34: =IF(MOD(ROW()-2,2)=0, INDIRECT("Sheet1!D" &4+((ROW()-2)/2)-2), "") -> weHdeh 'ella 3ashra
B35: =IF(MOD(ROW()-3,2)=0, INDIRECT("Sheet1!E" &4+((ROW()-3)/2)-2), "") -> وحدة إلاّ عَشرَة
A36: =IF(MOD(ROW()-2,2)=0, INDIRECT("Sheet1!A" &4+((ROW()-2)/2)-2), "") -> 5 past 6 | B36: =IF(MOD(ROW()-2,2)=0, INDIRECT("Sheet1!D" &4+((ROW()-2)/2)-2), "") -> setteh w khamseh
B37: =IF(MOD(ROW()-3,2)=0, INDIRECT("Sheet1!E" &4+((ROW()-3)/2)-2), "") -> ستّة و خَمسة
A38: =IF(MOD(ROW()-2,2)=0, INDIRECT("Sheet1!A" &4+((ROW()-2)/2)-2), "") -> 5 to 6 | B38: =IF(MOD(ROW()-2,2)=0, INDIRECT("Sheet1!D" &4+((ROW()-2)/2)-2), "") -> setteh 'ella khamseh
B39: =IF(MOD(ROW()-3,2)=0, INDIRECT("Sheet1!E" &4+((ROW()-3)/2)-2), "") -> ستّة إلاّ خَمسة
A40: =IF(MOD(ROW()-2,2)=0, INDIRECT("Sheet1!A" &4+((ROW()-2)/2)-2), "") -> 0.48958333 | B40: =IF(MOD(ROW()-2,2)=0, INDIRECT("Sheet1!D" &4+((ROW()-2)/2)-2), "") -> tna3sh 'ella rebe3
B41: =IF(MOD(ROW()-3,2)=0, INDIRECT("Sheet1!E" &4+((ROW()-3)/2)-2), "") -> تنعش و ربع
...

Sheet Sheet2
A1: Name | B1: Translit. | C1: Value (IPA) | D1: Contextual forms | G1: Isolated
D2: Final | E2: Medial | F2: Initial
A3: alif | B3: ā / ’ (also ʾ ) | C3: various, | D3: ـا | E3: ـا | F3: ا | G3: ا
C4: including /aː/ [a]
A5: bā’ | B5: b | C5: /b/ | D5: ـب | E5: ـبـ | F5: بـ | G5: ب
C6: (sometimes /p/ in loanwords)[b]
A7: tā’ | B7: t | C7: /t/ | D7: ـت | E7: ـتـ | F7: تـ | G7: ت
A8: thā’ | B8: th (also ṯ ) | C8: /θ/ | D8: ـث | E8: ـثـ | F8: ثـ | G8: ث
A9: jīm | B9: j (also ǧ, g ) | C9: [d͡ʒ] ~ [ʒ] ~ [ɡ] [c] | D9: ـج | E9: ـجـ | F9: جـ | G9: ج
A10: ḥā’ | B10: ḥ | C10: /ħ/ | D10: ـح | E10: ـحـ | F10: حـ | G10: ح
A11: khā’ | B11: kh (also ḫ, ḵ ) | C11: /x/ | D11: ـخ | E11: ـخـ | F11: خـ | G11: خ
A12: dāl | B12: d | C12: /d/ | D12: ـد | E12: ـد | F12: د | G12: د
A13: dhāl | B13: dh (also ḏ ) | C13: /ð/ | D13: ـذ | E13: ـذ | F13: ذ | G13: ذ
A14: rā’ | B14: r | C14: /r/ | D14: ـر | E14: ـر | F14: ر | G14: ر
A15: zayn / zāy | B15: z | C15: /z/ | D15: ـز | E15: ـز | F15: ز | G15: ز
A16: sīn | B16: s | C16: /s/ | D16: ـس | E16: ـسـ | F16: سـ | G16: س
A17: shīn | B17: sh (also š ) | C17: /ʃ/ | D17: ـش | E17: ـشـ | F17: شـ | G17: ش
A18: ṣād | B18: ṣ | C18: /sˤ/ | D18: ـص | E18: ـصـ | F18: صـ | G18: ص
... A23: ghayn | B23: gh (also ġ, ḡ ) | C23: /ɣ/ | D23: ـغ | E23: ـغـ | F23: غـ | G23: غ
C24: (sometimes /ɡ/ in loanwords)[c]
A25: fā’ | B25: f | C25: /f/ | D25: ـف | E25: ـفـ | F25: فـ | G25: ف [d]
C26: (sometimes /v/ in loanwords)[b]
A27: qāf | B27: q | C27: /q/ | D27: ـق | E27: ـقـ | F27: قـ | G27: ق [d]
C28: (sometimes /ɡ/ in loanwords)[c]
A29: kāf | B29: k | C29: /k/ | D29: ـك | E29: ـكـ | F29: كـ | G29: ك
C30: (sometimes /ɡ/ in loanwords)[c]
A31: lām | B31: l | C31: /l/ | D31: ـل | E31: ـلـ | F31: لـ | G31: ل
A32: mīm | B32: m | C32: /m/ | D32: ـم | E32: ـمـ | F32: مـ | G32: م
A33: nūn | B33: n | C33: /n/ | D33: ـن | E33: ـنـ | F33: نـ | G33: ن
A34: hā’ | B34: h | C34: /h/ | D34: ـه | E34: ـهـ | F34: هـ | G34: ه
A35: wāw | B35: w / ū / aw | C35: /w/, /uː/, /aw/, | D35: ـو | E35: ـو | F35: و | G35: و
C36: sometimes /u/, /o/, and /oː/ in loanwords
A37: yā’ | B37: y / ī / ay | C37: /j/, /iː/, /aj/, | D37: ـي | E37: ـيـ | F37: يـ | G37: ي [e]
C38: sometimes /i/, /e/, and /eː/ in loanwords

Sheet Sheet5
A1: =IF(MOD(ROW()-2,3)=0, INDIRECT("Sheet1!A" &4+((ROW()-2)/3)-2), "")
D2: =IF(MOD(ROW()-2,2)=0, INDIRECT("Sheet1!A" &4+((ROW()-2)/2)-2), "") -> Time | E2: =IF(MOD(ROW()-2,2)=0, INDIRECT("Sheet1!D" &4+((ROW()-2)/2)-2), "") -> wa'et
E3: =IF(MOD(ROW()-3,2)=0, INDIRECT("Sheet1!E" &4+((ROW()-3)/2)-2), "") -> وَقت
A4: =IF(MOD(ROW()-2,2)=0, INDIRECT("Sheet1!A" &4+((ROW()-2)/2)-2), "") -> Timing | B4: =IF(MOD(ROW()-2,2)=0, INDIRECT("Sheet1!D" &4+((ROW()-2)/2)-2), "") -> touw'eet | D4: =IF(MOD(ROW()-2,2)=0, INDIRECT("Sheet1!A" &4+((ROW()-2)/2)-2), "") -> Timing | E4: =IF(MOD(ROW()-2,2)=0, INDIRECT("Sheet1!D" &4+((ROW()-2)/2)-2), "") -> touw'eet
A5: =IF(MOD(ROW()-2,2)=0, INDIRECT("Sheet1!A" &4+((ROW()-2)/2)-2), "") | B5: =IF(MOD(ROW()-3,2)=0, INDIRECT("Sheet1!E" &4+((ROW()-3)/2)-2), "") -> توقيت | E5: =IF(MOD(ROW()-3,2)=0, INDIRECT("Sheet1!E" &4+((ROW()-3)/2)-2), "") -> توقيت
A6: =IF(MOD(ROW()-2,2)=0, INDIRECT("Sheet1!A" &4+((ROW()-2)/2)-2), "") -> Hour | B6: =IF(MOD(ROW()-2,2)=0, INDIRECT("Sheet1!D" &4+((ROW()-2)/2)-2), "") -> sei3a | D6: =IF(MOD(ROW()-2,2)=0, INDIRECT("Sheet1!A" &4+((ROW()-2)/2)-2), "") -> Hour | E6: =IF(MOD(ROW()-2,2)=0, INDIRECT("Sheet1!D" &4+((ROW()-2)/2)-2), "") -> sei3a
B7: =IF(MOD(ROW()-3,2)=0, INDIRECT("Sheet1!E" &4+((ROW()-3)/2)-2), "") -> ساعَة | E7: =IF(MOD(ROW()-3,2)=0, INDIRECT("Sheet1!E" &4+((ROW()-3)/2)-2), "") -> ساعَة
B8: =IF(MOD(ROW()-2,2)=0, INDIRECT("Sheet1!D" &4+((ROW()-2)/2)-2), "") -> se3tein | D8: =IF(MOD(ROW()-2,2)=0, INDIRECT("Sheet1!A" &4+((ROW()-2)/2)-2), "") -> 2 hours | E8: =IF(MOD(ROW()-2,2)=0, INDIRECT("Sheet1!D" &4+((ROW()-2)/2)-2), "") -> se3tein
B9: =IF(MOD(ROW()-3,2)=0, INDIRECT("Sheet1!E" &4+((ROW()-3)/2)-2), "") -> ساعتين | E9: =IF(MOD(ROW()-3,2)=0, INDIRECT("Sheet1!E" &4+((ROW()-3)/2)-2), "") -> ساعتين
B10: =IF(MOD(ROW()-2,2)=0, INDIRECT("Sheet1!D" &4+((ROW()-2)/2)-2), "") -> se3at | D10: =IF(MOD(ROW()-2,2)=0, INDIRECT("Sheet1!A" &4+((ROW()-2)/2)-2), "") -> Hours | E10: =IF(MOD(ROW()-2,2)=0, INDIRECT("Sheet1!D" &4+((ROW()-2)/2)-2), "") -> se3at
B11: =IF(MOD(ROW()-3,2)=0, INDIRECT("Sheet1!E" &4+((ROW()-3)/2)-2), "") -> ساعات | E11: =IF(MOD(ROW()-3,2)=0, INDIRECT("Sheet1!E" &4+((ROW()-3)/2)-2), "") -> ساعات
B12: =IF(MOD(ROW()-2,2)=0, INDIRECT("Sheet1!D" &4+((ROW()-2)/2)-2), "") -> d'i'a | D12: =IF(MOD(ROW()-2,2)=0, INDIRECT("Sheet1!A" &4+((ROW()-2)/2)-2), "") -> Minute | E12: =IF(MOD(ROW()-2,2)=0, INDIRECT("Sheet1!D" &4+((ROW()-2)/2)-2), "") -> d'i'a
B13: =IF(MOD(ROW()-3,2)=0, INDIRECT("Sheet1!E" &4+((ROW()-3)/2)-2), "") -> دقيقَة | E13: =IF(MOD(ROW()-3,2)=0, INDIRECT("Sheet1!E" &4+((ROW()-3)/2)-2), "") -> دقيقَة
B14: =IF(MOD(ROW()-2,2)=0, INDIRECT("Sheet1!D" &4+((ROW()-2)/2)-2), "") -> d'i'tein | D14: =IF(MOD(ROW()-2,2)=0, INDIRECT("Sheet1!A" &4+((ROW()-2)/2)-2), "") -> 2 minutes | E14: =IF(MOD(ROW()-2,2)=0, INDIRECT("Sheet1!D" &4+((ROW()-2)/2)-2), "") -> d'i'tein
B15: =IF(MOD(ROW()-3,2)=0, INDIRECT("Sheet1!E" &4+((ROW()-3)/2)-2), "") -> دقيقتين | E15: =IF(MOD(ROW()-3,2)=0, INDIRECT("Sheet1!E" &4+((ROW()-3)/2)-2), "") -> دقيقتين
B16: =IF(MOD(ROW()-2,2)=0, INDIRECT("Sheet1!D" &4+((ROW()-2)/2)-2), "") -> da'eyi' | D16: =IF(MOD(ROW()-2,2)=0, INDIRECT("Sheet1!A" &4+((ROW()-2)/2)-2), "") -> Minutes | E16: =IF(MOD(ROW()-2,2)=0, INDIRECT("Sheet1!D" &4+((ROW()-2)/2)-2), "") -> da'eyi'
B17: =IF(MOD(ROW()-3,2)=0, INDIRECT("Sheet1!E" &4+((ROW()-3)/2)-2), "") -> دَقايق | E17: =IF(MOD(ROW()-3,2)=0, INDIRECT("Sheet1!E" &4+((ROW()-3)/2)-2), "") -> دَقايق
B18: =IF(MOD(ROW()-2,2)=0, INDIRECT("Sheet1!D" &4+((ROW()-2)/2)-2), "") -> seinyeh | D18: =IF(MOD(ROW()-2,2)=0, INDIRECT("Sheet1!A" &4+((ROW()-2)/2)-2), "") -> Second | E18: =IF(MOD(ROW()-2,2)=0, INDIRECT("Sheet1!D" &4+((ROW()-2)/2)-2), "") -> seinyeh
B19: =IF(MOD(ROW()-3,2)=0, INDIRECT("Sheet1!E" &4+((ROW()-3)/2)-2), "") -> ثانية | E19: =IF(MOD(ROW()-3,2)=0, INDIRECT("Sheet1!E" &4+((ROW()-3)/2)-2), "") -> ثانية
B20: =IF(MOD(ROW()-2,2)=0, INDIRECT("Sheet1!D" &4+((ROW()-2)/2)-2), "") -> senitein | D20: =IF(MOD(ROW()-2,2)=0, INDIRECT("Sheet1!A" &4+((ROW()-2)/2)-2), "") -> 2 seconds | E20: =IF(MOD(ROW()-2,2)=0, INDIRECT("Sheet1!D" &4+((ROW()-2)/2)-2), "") -> senitein
B21: =IF(MOD(ROW()-3,2)=0, INDIRECT("Sheet1!E" &4+((ROW()-3)/2)-2), "") -> ثانتين | E21: =IF(MOD(ROW()-3,2)=0, INDIRECT("Sheet1!E" &4+((ROW()-3)/2)-2), "") -> ثانتين
B22: =IF(MOD(ROW()-2,2)=0, INDIRECT("Sheet1!D" &4+((ROW()-2)/2)-2), "") -> saweineh | D22: =IF(MOD(ROW()-2,2)=0, INDIRECT("Sheet1!A" &4+((ROW()-2)/2)-2), "") -> Seconds | E22: =IF(MOD(ROW()-2,2)=0, INDIRECT("Sheet1!D" &4+((ROW()-2)/2)-2), "") -> saweineh
B23: =IF(MOD(ROW()-3,2)=0, INDIRECT("Sheet1!E" &4+((ROW()-3)/2)-2), "") -> ثواني | E23: =IF(MOD(ROW()-3,2)=0, INDIRECT("Sheet1!E" &4+((ROW()-3)/2)-2), "") -> ثواني
B24: =IF(MOD(ROW()-2,2)=0, INDIRECT("Sheet1!D" &4+((ROW()-2)/2)-2), "") -> abel el doher | D24: =IF(MOD(ROW()-2,2)=0, INDIRECT("Sheet1!A" &4+((ROW()-2)/2)-2), "") -> A.M | E24: =IF(MOD(ROW()-2,2)=0, INDIRECT("Sheet1!D" &4+((ROW()-2)/2)-2), "") -> abel el doher
B25: =IF(MOD(ROW()-3,2)=0, INDIRECT("Sheet1!E" &4+((ROW()-3)/2)-2), "") -> قَبل الضُهر | E25: =IF(MOD(ROW()-3,2)=0, INDIRECT("Sheet1!E" &4+((ROW()-3)/2)-2), "") -> قَبل الضُهر
B26: =IF(MOD(ROW()-2,2)=0, INDIRECT("Sheet1!D" &4+((ROW()-2)/2)-2), "") -> ba3ed el doher | D26: =IF(MOD(ROW()-2,2)=0, INDIRECT("Sheet1!A" &4+((ROW()-2)/2)-2), "") -> P.M | E26: =IF(MOD(ROW()-2,2)=0, INDIRECT("Sheet1!D" &4+((ROW()-2)/2)-2), "") -> ba3ed el doher
B27: =IF(MOD(ROW()-3,2)=0, INDIRECT("Sheet1!E" &4+((ROW()-3)/2)-2), "") -> بَعد الضُهر | E27: =IF(MOD(ROW()-3,2)=0, INDIRECT("Sheet1!E" &4+((ROW()-3)/2)-2), "") -> بَعد الضُهر
B28: =IF(MOD(ROW()-2,2)=0, INDIRECT("Sheet1!D" &4+((ROW()-2)/2)-2), "") -> m'akhar | D28: =IF(MOD(ROW()-2,2)=0, INDIRECT("Sheet1!A" &4+((ROW()-2)/2)-2), "") -> It's late | E28: =IF(MOD(ROW()-2,2)=0, INDIRECT("Sheet1!D" &4+((ROW()-2)/2)-2), "") -> m'akhar
B29: =IF(MOD(ROW()-3,2)=0, INDIRECT("Sheet1!E" &4+((ROW()-3)/2)-2), "") -> مأخَّر | E29: =IF(MOD(ROW()-3,2)=0, INDIRECT("Sheet1!E" &4+((ROW()-3)/2)-2), "") -> مأخَّر
B30: =IF(MOD(ROW()-2,2)=0, INDIRECT("Sheet1!D" &4+((ROW()-2)/2)-2), "") -> bakkeer | D30: =IF(MOD(ROW()-2,2)=0, INDIRECT("Sheet1!A" &4+((ROW()-2)/2)-2), "") -> It's early | E30: =IF(MOD(ROW()-2,2)=0, INDIRECT("Sheet1!D" &4+((ROW()-2)/2)-2), "") -> bakkeer
B31: =IF(MOD(ROW()-3,2)=0, INDIRECT("Sheet1!E" &4+((ROW()-3)/2)-2), "") -> بكّير | E31: =IF(MOD(ROW()-3,2)=0, INDIRECT("Sheet1!E" &4+((ROW()-3)/2)-2), "") -> بكّير
B32: =IF(MOD(ROW()-2,2)=0, INDIRECT("Sheet1!D" &4+((ROW()-2)/2)-2), "") -> addeh el sei3a? | D32: =IF(MOD(ROW()-2,2)=0, INDIRECT("Sheet1!A" &4+((ROW()-2)/2)-2), "") -> What time is it? | E32: =IF(MOD(ROW()-2,2)=0, INDIRECT("Sheet1!D" &4+((ROW()-2)/2)-2), "") -> addeh el sei3a?
B33: =IF(MOD(ROW()-3,2)=0, INDIRECT("Sheet1!E" &4+((ROW()-3)/2)-2), "") -> أدّي الساعَة؟ | E33: =IF(MOD(ROW()-3,2)=0, INDIRECT("Sheet1!E" &4+((ROW()-3)/2)-2), "") -> أدّي الساعَة؟
B34: =IF(MOD(ROW()-2,2)=0, INDIRECT("Sheet1!D" &4+((ROW()-2)/2)-2), "") -> weHdeh 'ella 3ashra | D34: =IF(MOD(ROW()-2,2)=0, INDIRECT("Sheet1!A" &4+((ROW()-2)/2)-2), "") -> 10 to 1 | E34: =IF(MOD(ROW()-2,2)=0, INDIRECT("Sheet1!D" &4+((ROW()-2)/2)-2), "") -> weHdeh 'ella 3ashra
B35: =IF(MOD(ROW()-3,2)=0, INDIRECT("Sheet1!E" &4+((ROW()-3)/2)-2), "") -> وحدة إلاّ عَشرَة | E35: =IF(MOD(ROW()-3,2)=0, INDIRECT("Sheet1!E" &4+((ROW()-3)/2)-2), "") -> وحدة إلاّ عَشرَة
B36: =IF(MOD(ROW()-2,2)=0, INDIRECT("Sheet1!D" &4+((ROW()-2)/2)-2), "") -> setteh w khamseh | D36: =IF(MOD(ROW()-2,2)=0, INDIRECT("Sheet1!A" &4+((ROW()-2)/2)-2), "") -> 5 past 6 | E36: =IF(MOD(ROW()-2,2)=0, INDIRECT("Sheet1!D" &4+((ROW()-2)/2)-2), "") -> setteh w khamseh
B37: =IF(MOD(ROW()-3,2)=0, INDIRECT("Sheet1!E" &4+((ROW()-3)/2)-2), "") -> ستّة و خَمسة | E37: =IF(MOD(ROW()-3,2)=0, INDIRECT("Sheet1!E" &4+((ROW()-3)/2)-2), "") -> ستّة و خَمسة
B38: =IF(MOD(ROW()-2,2)=0, INDIRECT("Sheet1!D" &4+((ROW()-2)/2)-2), "") -> setteh 'ella khamseh | D38: =IF(MOD(ROW()-2,2)=0, INDIRECT("Sheet1!A" &4+((ROW()-2)/2)-2), "") -> 5 to 6 | E38: =IF(MOD(ROW()-2,2)=0, INDIRECT("Sheet1!D" &4+((ROW()-2)/2)-2), "") -> setteh 'ella khamseh
B39: =IF(MOD(ROW()-3,2)=0, INDIRECT("Sheet1!E" &4+((ROW()-3)/2)-2), "") -> ستّة إلاّ خَمسة | E39: =IF(MOD(ROW()-3,2)=0, INDIRECT("Sheet1!E" &4+((ROW()-3)/2)-2), "") -> ستّة إلاّ خَمسة
B40: =IF(MOD(ROW()-2,2)=0, INDIRECT("Sheet1!D" &4+((ROW()-2)/2)-2), "") -> tna3sh 'ella rebe3 | D40: =IF(MOD(ROW()-2,2)=0, INDIRECT("Sheet1!A" &4+((ROW()-2)/2)-2), "") -> 0.48958333 | E40: =IF(MOD(ROW()-2,2)=0, INDIRECT("Sheet1!D" &4+((ROW()-2)/2)-2), "") -> tna3sh 'ella rebe3
...

Sheet Sheet4
A1: =HYPERLINK("https://www.youtube.com/watch?v=e_dFFaECK5E","Video Lesson 4") -> Video Lesson 4 | B1: 1- basic language | C1: 1- numbers | D1: 1 | E1: 1 | F1: =HYPERLINK("https://www.youtube.com/watch?v=YMwQ4agNMPI","Video Lesson '2nd Valentine'") -> Video Lesson '2nd Valentine' | G1: Video Lesson '2nd Valentine' | H1: https://www.youtube.com/watch?v=YMwQ4agNMPI | M1: ="=hyperlink"&"("&""""&H1&""""&","&""""&G1&""""&")" -> =hyperlink("https://www.youtube.com/watch?v=YMwQ4agNMPI","Video Lesson '2nd Valentine'")
E2: 1 | F2: =HYPERLINK("https://www.youtube.com/watch?v=EWu4a7ogxVA","Video Lesson 'Improvisation'") -> Video Lesson 'Improvisation' | G2: Video Lesson 'Improvisation' | H2: https://www.youtube.com/watch?v=EWu4a7ogxVA | M2: ="=hyperlink"&"("&""""&H2&""""&","&""""&G2&""""&")" -> =hyperlink("https://www.youtube.com/watch?v=EWu4a7ogxVA","Video Lesson 'Improvisation'")
A3: =HYPERLINK("https://www.youtube.com/watch?v=e_dFFaECK5E","Video Lesson 4") -> Video Lesson 4 | B3: 1- basic language | C3: 1- numbers | D3: 2 | E3: 2 | F3: =HYPERLINK("https://www.youtube.com/watch?v=QAEGmTKhMo4","Video Lesson 'Valentine'") -> Video Lesson 'Valentine' | G3: Video Lesson 'Valentine' | H3: https://www.youtube.com/watch?v=QAEGmTKhMo4 | M3: ="=hyperlink"&"("&""""&H3&""""&","&""""&G3&""""&")" -> =hyperlink("https://www.youtube.com/watch?v=QAEGmTKhMo4","Video Lesson 'Valentine'")
E4: 2 | F4: =HYPERLINK("https://www.youtube.com/watch?v=7iovf94e4uU","Video Lesson 1") -> Video Lesson 1 | G4: Video Lesson 1 | H4: https://www.youtube.com/watch?v=7iovf94e4uU | M4: ="=hyperlink"&"("&""""&H4&""""&","&""""&G4&""""&")" -> =hyperlink("https://www.youtube.com/watch?v=7iovf94e4uU","Video Lesson 1")
A5: =HYPERLINK("https://www.youtube.com/watch?v=e_dFFaECK5E","Video Lesson 4") -> Video Lesson 4 | B5: 1- basic language | C5: 1- numbers | D5: 3 | E5: 3 | F5: =HYPERLINK("https://www.youtube.com/watch?v=Ivl-D6m04C4","Video Lesson 10") -> Video Lesson 10 | G5: Video Lesson 10 | H5: https://www.youtube.com/watch?v=Ivl-D6m04C4 | M5: ="=hyperlink"&"("&""""&H5&""""&","&""""&G5&""""&")" -> =hyperlink("https://www.youtube.com/watch?v=Ivl-D6m04C4","Video Lesson 10")
E6: 3 | F6: =HYPERLINK("https://www.youtube.com/watch?v=1G46tEJOrww","Video Lesson 11") -> Video Lesson 11 | G6: Video Lesson 11 | H6: https://www.youtube.com/watch?v=1G46tEJOrww | M6: ="=hyperlink"&"("&""""&H6&""""&","&""""&G6&""""&")" -> =hyperlink("https://www.youtube.com/watch?v=1G46tEJOrww","Video Lesson 11")
A7: =HYPERLINK("https://www.youtube.com/watch?v=e_dFFaECK5E","Video Lesson 4") -> Video Lesson 4 | B7: 1- basic language | C7: 1- numbers | D7: 4 | E7: 4 | F7: =HYPERLINK("https://www.youtube.com/watch?v=4qB8qVfkH4A","Video Lesson 12") -> Video Lesson 12 | G7: Video Lesson 12 | H7: https://www.youtube.com/watch?v=4qB8qVfkH4A | M7: ="=hyperlink"&"("&""""&H7&""""&","&""""&G7&""""&")" -> =hyperlink("https://www.youtube.com/watch?v=4qB8qVfkH4A","Video Lesson 12")
E8: 4 | F8: =HYPERLINK("https://www.youtube.com/watch?v=CuxAdMsjkyY","Video Lesson 13") -> Video Lesson 13 | G8: Video Lesson 13 | H8: https://www.youtube.com/watch?v=CuxAdMsjkyY | M8: ="=hyperlink"&"("&""""&H8&""""&","&""""&G8&""""&")" -> =hyperlink("https://www.youtube.com/watch?v=CuxAdMsjkyY","Video Lesson 13")
A9: =HYPERLINK("https://www.youtube.com/watch?v=e_dFFaECK5E","Video Lesson 4") -> Video Lesson 4 | B9: 1- basic language | C9: 1- numbers | D9: 5 | E9: 5 | F9: =HYPERLINK("https://www.youtube.com/watch?v=CIw5yuG2h7k","Video Lesson 14") -> Video Lesson 14 | G9: Video Lesson 14 | H9: https://www.youtube.com/watch?v=CIw5yuG2h7k | M9: ="=hyperlink"&"("&""""&H9&""""&","&""""&G9&""""&")" -> =hyperlink("https://www.youtube.com/watch?v=CIw5yuG2h7k","Video Lesson 14")
E10: 5 | F10: =HYPERLINK("https://www.youtube.com/watch?v=mlf3S2Z-yzM","Video Lesson 15") -> Video Lesson 15 | G10: Video Lesson 15 | H10: https://www.youtube.com/watch?v=mlf3S2Z-yzM | M10: ="=hyperlink"&"("&""""&H10&""""&","&""""&G10&""""&")" -> =hyperlink("https://www.youtube.com/watch?v=mlf3S2Z-yzM","Video Lesson 15")
A11: =HYPERLINK("https://www.youtube.com/watch?v=e_dFFaECK5E","Video Lesson 4") -> Video Lesson 4 | B11: 1- basic language | C11: 1- numbers | D11: 6 | E11: 6 | F11: =HYPERLINK("https://www.youtube.com/watch?v=-9H0tokUVvc","Video Lesson 16") -> Video Lesson 16 | G11: Video Lesson 16 | H11: https://www.youtube.com/watch?v=-9H0tokUVvc | M11: ="=hyperlink"&"("&""""&H11&""""&","&""""&G11&""""&")" -> =hyperlink("https://www.youtube.com/watch?v=-9H0tokUVvc","Video Lesson 16")
E12: 6 | F12: =HYPERLINK("https://www.youtube.com/watch?v=FpQEAG3hsdA","Video Lesson 17") -> Video Lesson 17 | G12: Video Lesson 17 | H12: https://www.youtube.com/watch?v=FpQEAG3hsdA | M12: ="=hyperlink"&"("&""""&H12&""""&","&""""&G12&""""&")" -> =hyperlink("https://www.youtube.com/watch?v=FpQEAG3hsdA","Video Lesson 17")
A13: =HYPERLINK("https://www.youtube.com/watch?v=e_dFFaECK5E","Video Lesson 4") -> Video Lesson 4 | B13: 1- basic language | C13: 1- numbers | D13: 7 | E13: 7 | F13: =HYPERLINK("https://www.youtube.com/watch?v=Y56hvBhqBaQ","Video Lesson 18") -> Video Lesson 18 | G13: Video Lesson 18 | H13: https://www.youtube.com/watch?v=Y56hvBhqBaQ | M13: ="=hyperlink"&"("&""""&H13&""""&","&""""&G13&""""&")" -> =hyperlink("https://www.youtube.com/watch?v=Y56hvBhqBaQ","Video Lesson 18")
E14: 7 | F14: =HYPERLINK("https://www.youtube.com/watch?v=Xop5dt-yhOA","Video Lesson 19") -> Video Lesson 19 | G14: Video Lesson 19 | H14: https://www.youtube.com/watch?v=Xop5dt-yhOA | M14: ="=hyperlink"&"("&""""&H14&""""&","&""""&G14&""""&")" -> =hyperlink("https://www.youtube.com/watch?v=Xop5dt-yhOA","Video Lesson 19")
A15: =HYPERLINK("https://www.youtube.com/watch?v=e_dFFaECK5E","Video Lesson 4") -> Video Lesson 4 | B15: 1- basic language | C15: 1- numbers | D15: 8 | E15: 8 | F15: =HYPERLINK("https://www.youtube.com/watch?v=E-TjOWZ5YQ0","Video Lesson 2") -> Video Lesson 2 | G15: Video Lesson 2 | H15: https://www.youtube.com/watch?v=E-TjOWZ5YQ0 | M15: ="=hyperlink"&"("&""""&H15&""""&","&""""&G15&""""&")" -> =hyperlink("https://www.youtube.com/watch?v=E-TjOWZ5YQ0","Video Lesson 2")
E16: 8 | F16: =HYPERLINK("https://www.youtube.com/watch?v=Sjl8iPAcNo0","Video Lesson 20") -> Video Lesson 20 | G16: Video Lesson 20 | H16: https://www.youtube.com/watch?v=Sjl8iPAcNo0 | M16: ="=hyperlink"&"("&""""&H16&""""&","&""""&G16&""""&")" -> =hyperlink("https://www.youtube.com/watch?v=Sjl8iPAcNo0","Video Lesson 20")
A17: =HYPERLINK("https://www.youtube.com/watch?v=e_dFFaECK5E","Video Lesson 4") -> Video Lesson 4 | B17: 1- basic language | C17: 1- numbers | D17: 9 | E17: 9 | F17: =HYPERLINK("https://www.youtube.com/watch?v=jVxw8JRCMDk","Video Lesson 21") -> Video Lesson 21 | G17: Video Lesson 21 | H17: https://www.youtube.com/watch?v=jVxw8JRCMDk | M17: ="=hyperlink"&"("&""""&H17&""""&","&""""&G17&""""&")" -> =hyperlink("https://www.youtube.com/watch?v=jVxw8JRCMDk","Video Lesson 21")
E18: 9 | F18: =HYPERLINK("https://www.youtube.com/watch?v=kLZmQK8CWFU","Video Lesson 22") -> Video Lesson 22 | G18: Video Lesson 22 | H18: https://www.youtube.com/watch?v=kLZmQK8CWFU | M18: ="=hyperlink"&"("&""""&H18&""""&","&""""&G18&""""&")" -> =hyperlink("https://www.youtube.com/watch?v=kLZmQK8CWFU","Video Lesson 22")
A19: =HYPERLINK("https://www.youtube.com/watch?v=e_dFFaECK5E","Video Lesson 4") -> Video Lesson 4 | B19: 1- basic language | C19: 1- numbers | D19: 10 | E19: 10 | F19: =HYPERLINK("https://www.youtube.com/watch?v=RmEAQDsTTaE","Video Lesson 23") -> Video Lesson 23 | G19: Video Lesson 23 | H19: https://www.youtube.com/watch?v=RmEAQDsTTaE | M19: ="=hyperlink"&"("&""""&H19&""""&","&""""&G19&""""&")" -> =hyperlink("https://www.youtube.com/watch?v=RmEAQDsTTaE","Video Lesson 23")
E20: 10 | F20: =HYPERLINK("https://www.youtube.com/watch?v=M-mxlyVa6iM","Video Lesson 24") -> Video Lesson 24 | G20: Video Lesson 24 | H20: https://www.youtube.com/watch?v=M-mxlyVa6iM | M20: ="=hyperlink"&"("&""""&H20&""""&","&""""&G20&""""&")" -> =hyperlink("https://www.youtube.com/watch?v=M-mxlyVa6iM","Video Lesson 24")
A21: =HYPERLINK("https://www.youtube.com/watch?v=e_dFFaECK5E","Video Lesson 4") -> Video Lesson 4 | B21: 1- basic language | C21: 1- numbers | D21: 11 | E21: 11 | F21: =HYPERLINK("https://www.youtube.com/watch?v=QXklxwQ4px8","Video Lesson 3.1") -> Video Lesson 3.1 | G21: Video Lesson 3.1 | H21: https://www.youtube.com/watch?v=QXklxwQ4px8 | M21: ="=hyperlink"&"("&""""&H21&""""&","&""""&G21&""""&")" -> =hyperlink("https://www.youtube.com/watch?v=QXklxwQ4px8","Video Lesson 3.1")
E22: 11 | F22: =HYPERLINK("https://www.youtube.com/watch?v=bbpaAUOv8dE","Video Lesson 3.2") -> Video Lesson 3.2 | G22: Video Lesson 3.2 | H22: https://www.youtube.com/watch?v=bbpaAUOv8dE | M22: ="=hyperlink"&"("&""""&H22&""""&","&""""&G22&""""&")" -> =hyperlink("https://www.youtube.com/watch?v=bbpaAUOv8dE","Video Lesson 3.2")
A23: =HYPERLINK("https://www.youtube.com/watch?v=CIw5yuG2h7k","Video Lesson 14") -> Video Lesson 14 | B23: 1- basic language | C23: 2- days | D23: 1 | E23: 12 | F23: =HYPERLINK("https://www.youtube.com/watch?v=e_dFFaECK5E","Video Lesson 4") -> Video Lesson 4 | G23: Video Lesson 4 | H23: https://www.youtube.com/watch?v=e_dFFaECK5E | M23: ="=hyperlink"&"("&""""&H23&""""&","&""""&G23&""""&")" -> =hyperlink("https://www.youtube.com/watch?v=e_dFFaECK5E","Video Lesson 4")
E24: 12 | F24: =HYPERLINK("https://www.youtube.com/watch?v=HPUSR1ERIv0","Video Lesson 5") -> Video Lesson 5 | G24: Video Lesson 5 | H24: https://www.youtube.com/watch?v=HPUSR1ERIv0 | M24: ="=hyperlink"&"("&""""&H24&""""&","&""""&G24&""""&")" -> =hyperlink("https://www.youtube.com/watch?v=HPUSR1ERIv0","Video Lesson 5")
A25: =HYPERLINK("https://www.youtube.com/watch?v=CIw5yuG2h7k","Video Lesson 14") -> Video Lesson 14 | B25: 1- basic language | C25: 2- days | D25: 2 | E25: 13 | F25: =HYPERLINK("https://www.youtube.com/watch?v=DfQwYS9JfME","Video Lesson 6") -> Video Lesson 6 | G25: Video Lesson 6 | H25: https://www.youtube.com/watch?v=DfQwYS9JfME | M25: ="=hyperlink"&"("&""""&H25&""""&","&""""&G25&""""&")" -> =hyperlink("https://www.youtube.com/watch?v=DfQwYS9JfME","Video Lesson 6")
E26: 13 | F26: =HYPERLINK("https://www.youtube.com/watch?v=kN_Mk1vvvzI","Video Lesson 7") -> Video Lesson 7 | G26: Video Lesson 7 | H26: https://www.youtube.com/watch?v=kN_Mk1vvvzI | M26: ="=hyperlink"&"("&""""&H26&""""&","&""""&G26&""""&")" -> =hyperlink("https://www.youtube.com/watch?v=kN_Mk1vvvzI","Video Lesson 7")
A27: =HYPERLINK("https://www.youtube.com/watch?v=CIw5yuG2h7k","Video Lesson 14") -> Video Lesson 14 | B27: 1- basic language | C27: 2- days | D27: 3 | E27: 14 | F27: =HYPERLINK("https://www.youtube.com/watch?v=SGeR9HfhVRA","Video Lesson 8") -> Video Lesson 8 | G27: Video Lesson 8 | H27: https://www.youtube.com/watch?v=SGeR9HfhVRA | M27: ="=hyperlink"&"("&""""&H27&""""&","&""""&G27&""""&")" -> =hyperlink("https://www.youtube.com/watch?v=SGeR9HfhVRA","Video Lesson 8")
E28: 14 | F28: =HYPERLINK("https://www.youtube.com/watch?v=KUWhrhaqHsg","Video Lesson 9") -> Video Lesson 9 | G28: Video Lesson 9 | H28: https://www.youtube.com/watch?v=KUWhrhaqHsg | M28: ="=hyperlink"&"("&""""&H28&""""&","&""""&G28&""""&")" -> =hyperlink("https://www.youtube.com/watch?v=KUWhrhaqHsg","Video Lesson 9")
A29: =HYPERLINK("https://www.youtube.com/watch?v=CIw5yuG2h7k","Video Lesson 14") -> Video Lesson 14 | B29: 1- basic language | C29: 2- days | D29: 4 | E29: 15
E30: 15
A31: =HYPERLINK("https://www.youtube.com/watch?v=CIw5yuG2h7k","Video Lesson 14") -> Video Lesson 14 | B31: 1- basic language | C31: 2- days | D31: 5 | E31: 16
E32: 16
A33: =HYPERLINK("https://www.youtube.com/watch?v=CIw5yuG2h7k","Video Lesson 14") -> Video Lesson 14 | B33: 1- basic language | C33: 2- days | D33: 6 | E33: 17
E34: 17
A35: =HYPERLINK("https://www.youtube.com/watch?v=CIw5yuG2h7k","Video Lesson 14") -> Video Lesson 14 | B35: 1- basic language | C35: 2- days | D35: 7 | E35: 18
E36: 18
A37: =HYPERLINK("https://www.youtube.com/watch?v=kN_Mk1vvvzI","Video Lesson 7") -> Video Lesson 7 | B37: 1- basic language | C37: 2- days | D37: 8 | E37: 19
E38: 19
A39: =HYPERLINK("https://www.youtube.com/watch?v=kN_Mk1vvvzI","Video Lesson 7") -> Video Lesson 7 | B39: 1- basic language | C39: 2- days | D39: 9 | E39: 20
E40: 20
...

Sheet Sheet3
A1: ا
A2: ب
A3: ت
A4: ث
A5: ج
A6: ح
A7: خ
A8: د
A9: ذ
A10: ر
A11: ز
A12: س
... A28: ي

Sheet Text

Sheet crosswords
A1: Hello | B1: marHaba | C1: =A1&" / "&B1 -> Hello / marHaba | E1: =A1&" "&B1 -> Hello marHaba | G1: =A1&":"&B1 -> Hello:marHaba | J1: About:3an | L1: 1 | M1: About/3an | O1: Heart | P1: aleb
A2: I work | B2: beshteghil | C2: =A2&" / "&B2 -> I work / beshteghil | E2: =A2&" "&B2 -> I work beshteghil | G2: =A2&":"&B2 -> I work:beshteghil | J2: Anger:to3seeb | L2: 1 | M2: Anger/to3seeb | O2: I work | P2: beshteghil
A3: My name is | B3: esmeh | C3: =A3&" / "&B3 -> My name is / esmeh | E3: =A3&" "&B3 -> My name is esmeh | G3: =A3&":"&B3 -> My name is:esmeh | J3: Brown:benneh | L3: 1 | M3: Brown/benneh | O3: nearest | P3: a'rab
A4: Welcome | B4: ahla w sahla | C4: =A4&" / "&B4 -> Welcome / ahla w sahla | E4: =A4&" "&B4 -> Welcome ahla w sahla | G4: =A4&":"&B4 -> Welcome:ahla w sahla | J4: Dress:fostan | L4: 1 | M4: Dress/fostan | O4: Rice | P4: rezz
A5: Excuse me | B5: 3afwan | C5: =A5&" / "&B5 -> Excuse me / 3afwan | E5: =A5&" "&B5 -> Excuse me 3afwan | G5: =A5&":"&B5 -> Excuse me:3afwan | J5: Glasses:3wayneit | L5: 1 | M5: Glasses/3wayneit | O5: street | P5: sheiri3
A6: money | B6: masareh | C6: =A6&" / "&B6 -> money / masareh | E6: =A6&" "&B6 -> money masareh | G6: =A6&":"&B6 -> money :masareh | J6: High heels:scarbeeneh | L6: 1 | M6: High heels/scarbeeneh | O6: Today | P6: lyom
A7: How much | B7: addeh | C7: =A7&" / "&B7 -> How much / addeh | E7: =A7&" "&B7 -> How much addeh | G7: =A7&":"&B7 -> How much:addeh | J7: kids:wleid | L7: 1 | M7: kids/wleid | O7: And | P7: wa
A8: map | B8: khareeta | C8: =A8&" / "&B8 -> map / khareeta | E8: =A8&" "&B8 -> map khareeta | G8: =A8&":"&B8 -> map :khareeta | J8: Left :shmeil | L8: 1 | M8: Left /shmeil | O8: Four | P8: arb3a
A9: question | B9: sou'aal | C9: =A9&" / "&B9 -> question / sou'aal | E9: =A9&" "&B9 -> question sou'aal | G9: =A9&":"&B9 -> question:sou'aal | J9: Sunday:aHad | L9: 1 | M9: Sunday/aHad | O9: Hello | P9: marHaba
A10: room | B10: ouda | C10: =A10&" / "&B10 -> room / ouda | E10: =A10&" "&B10 -> room ouda | G10: =A10&":"&B10 -> room :ouda | J10: Anxiety:ala' | L10: 2 | M10: Anxiety/ala' | O10: I | P10: ana
A11: week | B11: jem3a | C11: =A11&" / "&B11 -> week / jem3a | E11: =A11&" "&B11 -> week jem3a | G11: =A11&":"&B11 -> week :jem3a | J11: Eight :tmeineh | L11: 2 | M11: Eight /tmeineh | O11: Night | P11: leil
A12: cheaper | B12: arkhas | C12: =A12&" / "&B12 -> cheaper / arkhas | E12: =A12&" "&B12 -> cheaper arkhas | G12: =A12&":"&B12 -> cheaper:arkhas | J12: Grass:hasheesh | L12: 2 | M12: Grass/hasheesh | O12: Nine | P12: tes3a
... A38: Noon | B38: doher | C38: =A38&" / "&B38 -> Noon / doher | E38: =A38&" "&B38 -> Noon doher | G38: =A38&":"&B38 -> Noon :doher | J38: Fish:samak | L38: 5 | M38: Fish/samak | O38: She | P38: hiyeh
A39: Night | B39: leil | G39: =A39&":"&B39 -> Night :leil | J39: Gun:fared | L39: 5 | M39: Gun/fared | O39: Welcome | P39: ahla w sahla
A40: Autumn | B40: khareef | G40: =A40&":"&B40 -> Autumn :khareef | J40: How:kif | L40: 5 | M40: How/kif | O40: Orgasm | P40: nashweh
A41: Winter | B41: sheteh | G41: =A41&":"&B41 -> Winter :sheteh | J41: Morning :sobeH | L41: 5 | M41: Morning /sobeH | O41: What | P41: shou
A42: Spring | B42: rabee3 | G42: =A42&":"&B42 -> Spring :rabee3 | J42: Spring :rabee3 | L42: 5 | M42: Spring /rabee3 | O42: Pessimism | P42: tashei'oum
A43: bed | B43: takhet | G43: =A43&":"&B43 -> bed :takhet | J43: Three :tleiteh | L43: 5 | M43: Three /tleiteh | O43: When | P43: lamma
A44: Home | B44: beit | G44: =A44&":"&B44 -> Home :beit | J44: coffee:ahweh | L44: 6 | M44: coffee/ahweh | O44: Pink | P44: zahreh
A45: Apartement | B45: she'a | G45: =A45&":"&B45 -> Apartement :she'a | J45: Five :khamseh | L45: 6 | M45: Five /khamseh | O45: Six | P45: setteh
A46: rent | B46: ajaar | G46: =A46&":"&B46 -> rent :ajaar | J46: He:howeh | L46: 6 | M46: He/howeh | O46: Where | P46: wein
A47: bathroom | B47: Hemmeim | G47: =A47&":"&B47 -> bathroom:Hemmeim | J47: I drink coffee everyday:beshrab ahweh kel yom | L47: 6 | M47: Straight /deghreh | O47: So | P47: fa
A48: tomorrow | B48: bukra | G48: =A48&":"&B48 -> tomorrow :bukra | J48: My name is:esmeh | L48: 6 | M48: Thursday/khamees | O48: Winter | P48: sheteh
A49: And | B49: wa | G49: =A49&":"&B49 -> And:wa | J49: Straight :deghreh | L49: 6 | M49: After/ba3dein | O49: Pride | P49: fakher
A50: So | B50: fa | G50: =A50&":"&B50 -> So:fa | J50: Thursday:khamees | L50: 6 | M50: Because/la'enno | O50: Zero | P50: sefer
... A53: When | B53: lamma | G53: =A53&":"&B53 -> When:lamma | J53: Flower:zahra | L53: 7 | M53: I work/beshteghil | O53: rent | P53: ajaar
A54: From | B54: men | G54: =A54&":"&B54 -> From:men | J54: Heart :aleb | L54: 7 | M54: nearest/a'rab
A55: On | B55: 3ala | G55: =A55&":"&B55 -> On:3ala | J55: I work:beshteghil | L55: 7 | M55: Rice/rezz
A56: About | B56: 3an | G56: =A56&":"&B56 -> About:3an | J56: nearest:a'rab | L56: 7 | M56: street /sheiri3
A57: That | B57: enno | G57: =A57&":"&B57 -> That:enno | J57: Rice:rezz | L57: 7 | M57: Today /lyom
A58: Because | B58: la'enno | G58: =A58&":"&B58 -> Because:la'enno | J58: street :sheiri3 | L58: 7 | M58: And/wa
A59: Shirt | B59: ameess | G59: =A59&":"&B59 -> Shirt:ameess | J59: Today :lyom | L59: 7 | M59: Four /arb3a
A60: High heels | B60: scarbeeneh | G60: =A60&":"&B60 -> High heels:scarbeeneh | J60: And:wa | L60: 8 | M60: Hello/marHaba
A61: Shoe | B61: sobbat | G61: =A61&":"&B61 -> Shoe:sobbat | J61: Four :arb3a | L61: 8 | M61: I/ana
A62: Dress | B62: fostan | G62: =A62&":"&B62 -> Dress:fostan | J62: Hello:marHaba | L62: 8 | M62: Night /leil
A63: Glasses | B63: 3wayneit | G63: =A63&":"&B63 -> Glasses:3wayneit | J63: I:ana | L63: 8 | M63: Nine /tes3a
A64: Family | B64: 3ayleh | G64: =A64&":"&B64 -> Family:3ayleh | J64: Night :leil | L64: 8 | M64: Right /yameen
A65: I | B65: ana | G65: =A65&":"&B65 -> I:ana | J65: Nine :tes3a | L65: 8 | M65: Summer /seif
... A104: kids | B104: wleid | G104: =A104&":"&B104 -> kids:wleid | J104: Purple:banafsajeh | L104: 20 | M104: rent /ajaar
A105: kiss | B105: bawseh | G105: =A105&":"&B105 -> kiss :bawseh | J105: question:sou'aal | L105: 21
...

Sheet wordsearch
A1: bayyeh | B1: 1 | F1: 1
A2: eshteghil | B2: 1 | F2: 1
A3: masareh | B3: 1 | F3: 1
A4: sayfiyeh | B4: 1 | F4: 1
A5: alf | B5: 2 | F5: 1
A6: ento | B6: 2 | F6: 1
A7: kol | B7: 2 | F7: 1
A8: ouda | B8: 2 | F8: 1
A9: ajaar | B9: 3 | F9: 1
A10: doher | B10: 3 | F10: 1
A11: khamees | B11: 3 | F11: 1
A12: mneikoul | B12: 3 | F12: 1
... A37: samak | B37: 3 | F37: 3
